Workbook

Sheet 使用说明
A1: 玄矶 Mystcrag｜珠子商品库导入模板 V1.0 简化优化版
A4: 填写顺序
A5: 步骤 | B5: 操作 | C5: 说明
A6: 1 | B6: 先填写「水晶主数据」 | C6: 一种水晶只录一行，例如海蓝宝。标签使用英文逗号分隔。
A7: 2 | B7: 再填写「珠子SKU」 | C7: 每个“水晶种类 + 形状 + 尺寸 + 工艺”对应一个 SKU；不按图片漂亮程度猜品质。
A8: 3 | B8: 可选填写「配件SKU」 | C8: 保留原配件录入结构；隔珠、吊坠、跑环等单独录入。
A10: 关键规则
A11: 规则 | B11: 要求
A12: 唯一标识 | B12: crystal_id、product_id、sku 不可重复；建议使用英文小写和连字符。
A13: 价格单位 | B13: CNY 售价/成本填写“分”，例如 ¥12.00 填 1200；TWD 填整数元。
A14: 图片 | B14: 推荐透明背景 PNG/WebP，正方形，至少 800×800；文件名需与图片文件夹一致。
A15: 合规 | B15: 只描述材质、外观与文化设计灵感，不填写医疗功效、保证效果或确定性运势表述。
A16: 导入状态 | B16: 每张数据表首列会自动提示“可导入 / 请补全必填 / 待填写”。
A18: 交付建议 | B18: 首批建议先录入 30–50 款主力 SKU，再补齐库存批次与真实图片。
A19: 颜色说明 | B19: 图片采用一张一行，优先保存当前批次实拍、原始来源和明确权限。
A20: 当前模板 | B20: 本版新增库存批次、图片资产与隔离的 AI 分析结果；原始模板未被覆盖。
A22: 品质与 AI 边界
A23: 品质口径 | B23: 市场品质仅允许 COMMERCIAL_A / NEAR_COMMERCIAL_A / UNKNOWN。
A24: 商业描述 | B24: A 级是市场/供应商常用商业描述，不是统一国家标准、实验室评级或宝石学结论。
A25: 不要求填写 | B25: 透明度、棉絮、冰裂、黑点、矿缺、包裹体、颜色均匀度、处理方式等专业判断。
A26: 图片规则 | B26: 一张图片一行；保存来源、授权、实拍/AI 属性，不由程序自动猜品质。
A27: AI 分析 | B27: 仅写入「AI分析结果」，明确为模型估算；不得覆盖正式商品数据。
A28: 低置信度 | B28: 填写 UNKNOWN 并标记 requires_manual_review=TRUE。
A29: 推荐门槛 | B29: 优先使用人工确认、真实批次图、有库存、有效价格、权限清晰且允许进入 AI 设计库的 SKU。
A30: 统一提示 | B30: 天然水晶不同珠子及不同批次可能存在颜色、纹理、棉裂和包裹体差异，具体以当前批次实拍图片为准。

Sheet 水晶主数据
A1: 水晶主数据｜一种水晶一行
A4: 导入状态 | B4: crystal_id* | C4: 中文名* | D4: 英文名* | E4: 矿物学名称* | F4: 宝石学信息 | G4: 颜色标签* | H4: 视觉标签* | I4: 风格标签* | J4: 情绪标签 | K4: 文化标签 | L4: 价格等级* | M4: 市场供应情况 | N4: 图片参考 | O4: 合规说明* | P4: 备注 | Q4: 负责人
A5: =IF(COUNTA(B5:Q5)=0,"待填写",IF(OR(B5="",C5="",D5="",E5="",G5="",H5="",I5="",NOT(ISNUMBER(L5)),O5=""),"请补全必填",IF(COUNTIF($B$5:$B$54,B5)>1,"ID重复",IF(ISNA(MATCH(M5,'_枚举'!$T$2:$T$5,0)),"枚举错误",IF(OR(NOT(ISNUMBER(L5)),L5<1,L5>5),"格式错误","可导入"))))) | B5: crystal-aquamarine | C5: 海蓝宝 | D5: Aquamarine | E5: Beryl | F5: family=Beryl;use=jewelry design reference | G5: blue,cool,translucent | H5: clear,ocean-blue,elegant | I5: minimal,contemporary-eastern | J5: calm-aesthetic | K5: design-inspiration-only | L5: 2 | M5: regular | N5: aquamarine.png | O5: 仅作材质与文化设计参考，不代表医疗或保证效果。 | P5: 示例，可修改
A6: =IF(COUNTA(B6:Q6)=0,"待填写",IF(OR(B6="",C6="",D6="",E6="",G6="",H6="",I6="",NOT(ISNUMBER(L6)),O6=""),"请补全必填",IF(COUNTIF($B$5:$B$54,B6)>1,"ID重复",IF(ISNA(MATCH(M6,'_枚举'!$T$2:$T$5,0)),"枚举错误",IF(OR(NOT(ISNUMBER(L6)),L6<1,L6>5),"格式错误","可导入"))))) | B6: crystal-moonstone | C6: 月光石 | D6: Moonstone | E6: Feldspar | F6: family=Feldspar;use=jewelry design reference | G6: white,blue,iridescent | H6: soft,glow,translucent | I6: romantic,minimal | J6: gentle-aesthetic | K6: design-inspiration-only | L6: 2 | M6: regular | N6: moonstone.png | O6: 仅作材质与文化设计参考，不代表医疗或保证效果。 | P6: 示例，可修改
A7: =IF(COUNTA(B7:Q7)=0,"待填写",IF(OR(B7="",C7="",D7="",E7="",G7="",H7="",I7="",NOT(ISNUMBER(L7)),O7=""),"请补全必填",IF(COUNTIF($B$5:$B$54,B7)>1,"ID重复",IF(ISNA(MATCH(M7,'_枚举'!$T$2:$T$5,0)),"枚举错误",IF(OR(NOT(ISNUMBER(L7)),L7<1,L7>5),"格式错误","可导入"))))) | B7: crystal-clear-quartz | C7: 白水晶 | D7: Clear Quartz | E7: Quartz | F7: family=Quartz;use=jewelry design reference | G7: clear,white,neutral | H7: clear,clean,transparent | I7: minimal,classic | J7: clean-aesthetic | K7: design-inspiration-only | L7: 1 | M7: regular | N7: clear-quartz.png | O7: 仅作材质与文化设计参考，不代表医疗或保证效果。 | P7: 示例，可修改
A8: =IF(COUNTA(B8:Q8)=0,"待填写",IF(OR(B8="",C8="",D8="",E8="",G8="",H8="",I8="",NOT(ISNUMBER(L8)),O8=""),"请补全必填",IF(COUNTIF($B$5:$B$54,B8)>1,"ID重复",IF(ISNA(MATCH(M8,'_枚举'!$T$2:$T$5,0)),"枚举错误",IF(OR(NOT(ISNUMBER(L8)),L8<1,L8>5),"格式错误","可导入"))))) | B8: crystal-amethyst | C8: 紫水晶 | D8: Amethyst | E8: Quartz | F8: family=Quartz;use=jewelry design reference | G8: purple,cool,deep | H8: purple,clear,deep | I8: elegant,contemporary-eastern | J8: quiet-aesthetic | K8: design-inspiration-only | L8: 2 | M8: regular | N8: amethyst.png | O8: 仅作材质与文化设计参考，不代表医疗或保证效果。 | P8: 示例，可修改
A9: =IF(COUNTA(B9:Q9)=0,"待填写",IF(OR(B9="",C9="",D9="",E9="",G9="",H9="",I9="",NOT(ISNUMBER(L9)),O9=""),"请补全必填",IF(COUNTIF($B$5:$B$54,B9)>1,"ID重复",IF(ISNA(MATCH(M9,'_枚举'!$T$2:$T$5,0)),"枚举错误",IF(OR(NOT(ISNUMBER(L9)),L9<1,L9>5),"格式错误","可导入"))))) | B9: crystal-rose-quartz | C9: 粉水晶 | D9: Rose Quartz | E9: Quartz | F9: family=Quartz;use=jewelry design reference | G9: pink,warm,soft | H9: pink,soft,milky | I9: romantic,minimal | J9: soft-aesthetic | K9: design-inspiration-only | L9: 1 | M9: regular | N9: rose-quartz.png | O9: 仅作材质与文化设计参考，不代表医疗或保证效果。 | P9: 示例，可修改
A10: =IF(COUNTA(B10:Q10)=0,"待填写",IF(OR(B10="",C10="",D10="",E10="",G10="",H10="",I10="",NOT(ISNUMBER(L10)),O10=""),"请补全必填",IF(COUNTIF($B$5:$B$54,B10)>1,"ID重复",IF(ISNA(MATCH(M10,'_枚举'!$T$2:$T$5,0)),"枚举错误",IF(OR(NOT(ISNUMBER(L10)),L10<1,L10>5),"格式错误","可导入")))))
A11: =IF(COUNTA(B11:Q11)=0,"待填写",IF(OR(B11="",C11="",D11="",E11="",G11="",H11="",I11="",NOT(ISNUMBER(L11)),O11=""),"请补全必填",IF(COUNTIF($B$5:$B$54,B11)>1,"ID重复",IF(ISNA(MATCH(M11,'_枚举'!$T$2:$T$5,0)),"枚举错误",IF(OR(NOT(ISNUMBER(L11)),L11<1,L11>5),"格式错误","可导入")))))
A12: =IF(COUNTA(B12:Q12)=0,"待填写",IF(OR(B12="",C12="",D12="",E12="",G12="",H12="",I12="",NOT(ISNUMBER(L12)),O12=""),"请补全必填",IF(COUNTIF($B$5:$B$54,B12)>1,"ID重复",IF(ISNA(MATCH(M12,'_枚举'!$T$2:$T$5,0)),"枚举错误",IF(OR(NOT(ISNUMBER(L12)),L12<1,L12>5),"格式错误","可导入")))))
A13: =IF(COUNTA(B13:Q13)=0,"待填写",IF(OR(B13="",C13="",D13="",E13="",G13="",H13="",I13="",NOT(ISNUMBER(L13)),O13=""),"请补全必填",IF(COUNTIF($B$5:$B$54,B13)>1,"ID重复",IF(ISNA(MATCH(M13,'_枚举'!$T$2:$T$5,0)),"枚举错误",IF(OR(NOT(ISNUMBER(L13)),L13<1,L13>5),"格式错误","可导入")))))
A14: =IF(COUNTA(B14:Q14)=0,"待填写",IF(OR(B14="",C14="",D14="",E14="",G14="",H14="",I14="",NOT(ISNUMBER(L14)),O14=""),"请补全必填",IF(COUNTIF($B$5:$B$54,B14)>1,"ID重复",IF(ISNA(MATCH(M14,'_枚举'!$T$2:$T$5,0)),"枚举错误",IF(OR(NOT(ISNUMBER(L14)),L14<1,L14>5),"格式错误","可导入")))))
A15: =IF(COUNTA(B15:Q15)=0,"待填写",IF(OR(B15="",C15="",D15="",E15="",G15="",H15="",I15="",NOT(ISNUMBER(L15)),O15=""),"请补全必填",IF(COUNTIF($B$5:$B$54,B15)>1,"ID重复",IF(ISNA(MATCH(M15,'_枚举'!$T$2:$T$5,0)),"枚举错误",IF(OR(NOT(ISNUMBER(L15)),L15<1,L15>5),"格式错误","可导入")))))
A16: =IF(COUNTA(B16:Q16)=0,"待填写",IF(OR(B16="",C16="",D16="",E16="",G16="",H16="",I16="",NOT(ISNUMBER(L16)),O16=""),"请补全必填",IF(COUNTIF($B$5:$B$54,B16)>1,"ID重复",IF(ISNA(MATCH(M16,'_枚举'!$T$2:$T$5,0)),"枚举错误",IF(OR(NOT(ISNUMBER(L16)),L16<1,L16>5),"格式错误","可导入")))))
A17: =IF(COUNTA(B17:Q17)=0,"待填写",IF(OR(B17="",C17="",D17="",E17="",G17="",H17="",I17="",NOT(ISNUMBER(L17)),O17=""),"请补全必填",IF(COUNTIF($B$5:$B$54,B17)>1,"ID重复",IF(ISNA(MATCH(M17,'_枚举'!$T$2:$T$5,0)),"枚举错误",IF(OR(NOT(ISNUMBER(L17)),L17<1,L17>5),"格式错误","可导入")))))
A18: =IF(COUNTA(B18:Q18)=0,"待填写",IF(OR(B18="",C18="",D18="",E18="",G18="",H18="",I18="",NOT(ISNUMBER(L18)),O18=""),"请补全必填",IF(COUNTIF($B$5:$B$54,B18)>1,"ID重复",IF(ISNA(MATCH(M18,'_枚举'!$T$2:$T$5,0)),"枚举错误",IF(OR(NOT(ISNUMBER(L18)),L18<1,L18>5),"格式错误","可导入")))))
A19: =IF(COUNTA(B19:Q19)=0,"待填写",IF(OR(B19="",C19="",D19="",E19="",G19="",H19="",I19="",NOT(ISNUMBER(L19)),O19=""),"请补全必填",IF(COUNTIF($B$5:$B$54,B19)>1,"ID重复",IF(ISNA(MATCH(M19,'_枚举'!$T$2:$T$5,0)),"枚举错误",IF(OR(NOT(ISNUMBER(L19)),L19<1,L19>5),"格式错误","可导入")))))
A20: =IF(COUNTA(B20:Q20)=0,"待填写",IF(OR(B20="",C20="",D20="",E20="",G20="",H20="",I20="",NOT(ISNUMBER(L20)),O20=""),"请补全必填",IF(COUNTIF($B$5:$B$54,B20)>1,"ID重复",IF(ISNA(MATCH(M20,'_枚举'!$T$2:$T$5,0)),"枚举错误",IF(OR(NOT(ISNUMBER(L20)),L20<1,L20>5),"格式错误","可导入")))))
A21: =IF(COUNTA(B21:Q21)=0,"待填写",IF(OR(B21="",C21="",D21="",E21="",G21="",H21="",I21="",NOT(ISNUMBER(L21)),O21=""),"请补全必填",IF(COUNTIF($B$5:$B$54,B21)>1,"ID重复",IF(ISNA(MATCH(M21,'_枚举'!$T$2:$T$5,0)),"枚举错误",IF(OR(NOT(ISNUMBER(L21)),L21<1,L21>5),"格式错误","可导入")))))
... A54: =IF(COUNTA(B54:Q54)=0,"待填写",IF(OR(B54="",C54="",D54="",E54="",G54="",H54="",I54="",NOT(ISNUMBER(L54)),O54=""),"请补全必填",IF(COUNTIF($B$5:$B$54,B54)>1,"ID重复",IF(ISNA(MATCH(M54,'_枚举'!$T$2:$T$5,0)),"枚举错误",IF(OR(NOT(ISNUMBER(L54)),L54<1,L54>5),"格式错误","可导入")))))

Sheet 珠子SKU
A1: 珠子 SKU｜水晶种类 + 形状 + 尺寸 + 工艺 = 一个 SKU
A3: 紫色表头中带 * 的字段为必填；市场品质只使用商业描述枚举，不代表国家标准或宝石学鉴定结论。
A4: 导入状态 | B4: product_id* | C4: sku* | D4: crystal_id* | E4: 商品名称* | F4: 形状* | G4: 直径_mm | H4: 长度_mm | I4: 宽度_mm | J4: 高度_mm | K4: 孔径_mm | L4: 切面类型 | M4: 市场品质等级* | N4: 品质信息来源* | O4: 品质备注 | P4: 计价单位* | Q4: 单位包含数量* | R4: 每串颗数 | S4: 串长_mm | T4: 默认损耗率* | U4: material_key* | V4: model_asset_key | W4: texture_asset_key | X4: 商品主图文件名* | Y4: 是否经过人工确认* | Z4: 是否适合进入AI设计库* | AA4: 是否上架* | AB4: 展示排序 | AC4: 备注 | AD4: 币种*（保留业务字段） | AE4: 售价_最小单位*（保留业务字段） | AF4: 成本_最小单位*（保留业务字段） | AG4: 可用库存*（保留业务字段）
A5: =IF(COUNTA(B5:AG5)=0,"待填写",IF(OR(B5="",C5="",D5="",E5="",F5="",AND(G5="",H5="",I5="",J5=""),M5="",N5="",P5="",NOT(ISNUMBER(Q5)),NOT(ISNUMBER(T5)),U5="",X5="",Y5="",Z5="",AA5="",AD5="",NOT(ISNUMBER(AE5)),NOT(ISNUMBER(AF5)),NOT(ISNUMBER(AG5))),"请补全必填",IF(OR(COUNTIF($B$5:$B$104,B5)>1,COUNTIF($C$5:$C$104,C5)>1),"ID重复",IF(COUNTIF('水晶主数据'!$B$5:$B$54,D5)=0,"关联不存在",IF(OR(ISNA(MATCH(F5,'_枚举'!$D$2:$D$7,0)),AND(L5<>"",ISNA(MATCH(L5,'_枚举'!$E$2:$E$6,0))),ISNA(MATCH(M5,'_枚举'!$A$2:$A$4,0)),ISNA(MATCH(N5,'_枚举'!$B$2:$B$5,0)),ISNA(MATCH(P5,'_枚举'!$F$2:$F$5,0)),ISNA(MATCH(Y5,'_枚举'!$C$2:$C$3,0)),ISNA(MATCH(Z5,'_枚举'!$C$2:$C$3,0)),ISNA(MATCH(AA5,'_枚举'!$C$2:$C$3,0)),ISNA(MATCH(AD5,'_枚举'!$G$2:$G$3,0))),"枚举错误",IF(OR(AND(G5<>"",OR(NOT(ISNUMBER(G5)),G5<=0)),AND(H5<>"",OR(NOT(ISNUMBER(H5)),H5<=0)),AND(I5<>"",OR(NOT(ISNUMBER(I5)),I5<=0)),AND(J5<>"",OR(NOT(ISNUMBER(J5)),J5<=0)),AND(K5<>"",OR(NOT(ISNUMBER(K5)),K5<=0)),NOT(ISNUMBER(Q5)),Q5<=0,AND(R5<>"",OR(NOT(ISNUMBER(R5)),R5<=0)),AND(S5<>"",OR(NOT(ISNUMBER(S5)),S5<=0)),NOT(ISNUMBER(T5)),T5<0,T5>1,NOT(ISNUMBER(AE5)),AE5<0,NOT(ISNUMBER(AF5)),AF5<0,NOT(ISNUMBER(AG5)),AG5<0,AND(AB5<>"",NOT(ISNUMBER(AB5)))),"格式错误",IF(AND(Z5="TRUE",OR(Y5<>"TRUE",M5="UNKNOWN")),"待人工复核","可导入"))))))) | B5: product-aquamarine-round-8 | C5: AQ-CNY-8 | D5: crystal-aquamarine | E5: 海蓝宝圆珠 8mm | F5: ROUND | G5: 8 | K5: 1 | L5: NONE | M5: COMMERCIAL_A | N5: MARKET_DESCRIPTION | O5: 普通市场货，颜色和纹理存在自然差异，以当前批次实拍图为准。 | P5: PER_BEAD | Q5: 1 | T5: 0.03 | U5: crystal-aquamarine-material-v1 | V5: sphere-round-8mm-v1 | W5: crystal-aquamarine-texture-v1 | X5: aquamarine-round-8.png | Y5: TRUE | Z5: TRUE | AA5: TRUE | AB5: 10 | AC5: 示例 | AD5: CNY | AE5: 1200 | AF5: 504 | AG5: 100
A6: =IF(COUNTA(B6:AG6)=0,"待填写",IF(OR(B6="",C6="",D6="",E6="",F6="",AND(G6="",H6="",I6="",J6=""),M6="",N6="",P6="",NOT(ISNUMBER(Q6)),NOT(ISNUMBER(T6)),U6="",X6="",Y6="",Z6="",AA6="",AD6="",NOT(ISNUMBER(AE6)),NOT(ISNUMBER(AF6)),NOT(ISNUMBER(AG6))),"请补全必填",IF(OR(COUNTIF($B$5:$B$104,B6)>1,COUNTIF($C$5:$C$104,C6)>1),"ID重复",IF(COUNTIF('水晶主数据'!$B$5:$B$54,D6)=0,"关联不存在",IF(OR(ISNA(MATCH(F6,'_枚举'!$D$2:$D$7,0)),AND(L6<>"",ISNA(MATCH(L6,'_枚举'!$E$2:$E$6,0))),ISNA(MATCH(M6,'_枚举'!$A$2:$A$4,0)),ISNA(MATCH(N6,'_枚举'!$B$2:$B$5,0)),ISNA(MATCH(P6,'_枚举'!$F$2:$F$5,0)),ISNA(MATCH(Y6,'_枚举'!$C$2:$C$3,0)),ISNA(MATCH(Z6,'_枚举'!$C$2:$C$3,0)),ISNA(MATCH(AA6,'_枚举'!$C$2:$C$3,0)),ISNA(MATCH(AD6,'_枚举'!$G$2:$G$3,0))),"枚举错误",IF(OR(AND(G6<>"",OR(NOT(ISNUMBER(G6)),G6<=0)),AND(H6<>"",OR(NOT(ISNUMBER(H6)),H6<=0)),AND(I6<>"",OR(NOT(ISNUMBER(I6)),I6<=0)),AND(J6<>"",OR(NOT(ISNUMBER(J6)),J6<=0)),AND(K6<>"",OR(NOT(ISNUMBER(K6)),K6<=0)),NOT(ISNUMBER(Q6)),Q6<=0,AND(R6<>"",OR(NOT(ISNUMBER(R6)),R6<=0)),AND(S6<>"",OR(NOT(ISNUMBER(S6)),S6<=0)),NOT(ISNUMBER(T6)),T6<0,T6>1,NOT(ISNUMBER(AE6)),AE6<0,NOT(ISNUMBER(AF6)),AF6<0,NOT(ISNUMBER(AG6)),AG6<0,AND(AB6<>"",NOT(ISNUMBER(AB6)))),"格式错误",IF(AND(Z6="TRUE",OR(Y6<>"TRUE",M6="UNKNOWN")),"待人工复核","可导入"))))))) | B6: product-moonstone-round-6 | C6: MO-CNY-6 | D6: crystal-moonstone | E6: 月光石圆珠 6mm | F6: ROUND | G6: 6 | K6: 1 | L6: NONE | M6: COMMERCIAL_A | N6: MARKET_DESCRIPTION | O6: 普通市场货，颜色和纹理存在自然差异，以当前批次实拍图为准。 | P6: PER_BEAD | Q6: 1 | T6: 0.03 | U6: crystal-moonstone-material-v1 | V6: sphere-round-6mm-v1 | W6: crystal-moonstone-texture-v1 | X6: moonstone-round-6.png | Y6: TRUE | Z6: TRUE | AA6: TRUE | AB6: 20 | AC6: 示例 | AD6: CNY | AE6: 800 | AF6: 336 | AG6: 100
A7: =IF(COUNTA(B7:AG7)=0,"待填写",IF(OR(B7="",C7="",D7="",E7="",F7="",AND(G7="",H7="",I7="",J7=""),M7="",N7="",P7="",NOT(ISNUMBER(Q7)),NOT(ISNUMBER(T7)),U7="",X7="",Y7="",Z7="",AA7="",AD7="",NOT(ISNUMBER(AE7)),NOT(ISNUMBER(AF7)),NOT(ISNUMBER(AG7))),"请补全必填",IF(OR(COUNTIF($B$5:$B$104,B7)>1,COUNTIF($C$5:$C$104,C7)>1),"ID重复",IF(COUNTIF('水晶主数据'!$B$5:$B$54,D7)=0,"关联不存在",IF(OR(ISNA(MATCH(F7,'_枚举'!$D$2:$D$7,0)),AND(L7<>"",ISNA(MATCH(L7,'_枚举'!$E$2:$E$6,0))),ISNA(MATCH(M7,'_枚举'!$A$2:$A$4,0)),ISNA(MATCH(N7,'_枚举'!$B$2:$B$5,0)),ISNA(MATCH(P7,'_枚举'!$F$2:$F$5,0)),ISNA(MATCH(Y7,'_枚举'!$C$2:$C$3,0)),ISNA(MATCH(Z7,'_枚举'!$C$2:$C$3,0)),ISNA(MATCH(AA7,'_枚举'!$C$2:$C$3,0)),ISNA(MATCH(AD7,'_枚举'!$G$2:$G$3,0))),"枚举错误",IF(OR(AND(G7<>"",OR(NOT(ISNUMBER(G7)),G7<=0)),AND(H7<>"",OR(NOT(ISNUMBER(H7)),H7<=0)),AND(I7<>"",OR(NOT(ISNUMBER(I7)),I7<=0)),AND(J7<>"",OR(NOT(ISNUMBER(J7)),J7<=0)),AND(K7<>"",OR(NOT(ISNUMBER(K7)),K7<=0)),NOT(ISNUMBER(Q7)),Q7<=0,AND(R7<>"",OR(NOT(ISNUMBER(R7)),R7<=0)),AND(S7<>"",OR(NOT(ISNUMBER(S7)),S7<=0)),NOT(ISNUMBER(T7)),T7<0,T7>1,NOT(ISNUMBER(AE7)),AE7<0,NOT(ISNUMBER(AF7)),AF7<0,NOT(ISNUMBER(AG7)),AG7<0,AND(AB7<>"",NOT(ISNUMBER(AB7)))),"格式错误",IF(AND(Z7="TRUE",OR(Y7<>"TRUE",M7="UNKNOWN")),"待人工复核","可导入"))))))) | B7: product-quartz-round-10 | C7: QU-CNY-10 | D7: crystal-clear-quartz | E7: 白水晶圆珠 10mm | F7: ROUND | G7: 10 | K7: 1 | L7: NONE | M7: COMMERCIAL_A | N7: MARKET_DESCRIPTION | O7: 普通市场货，颜色和纹理存在自然差异，以当前批次实拍图为准。 | P7: PER_BEAD | Q7: 1 | T7: 0.03 | U7: crystal-clear-quartz-material-v1 | V7: sphere-round-10mm-v1 | W7: crystal-clear-quartz-texture-v1 | X7: clear-quartz-round-10.png | Y7: TRUE | Z7: TRUE | AA7: TRUE | AB7: 30 | AC7: 示例 | AD7: CNY | AE7: 1000 | AF7: 420 | AG7: 100
A8: =IF(COUNTA(B8:AG8)=0,"待填写",IF(OR(B8="",C8="",D8="",E8="",F8="",AND(G8="",H8="",I8="",J8=""),M8="",N8="",P8="",NOT(ISNUMBER(Q8)),NOT(ISNUMBER(T8)),U8="",X8="",Y8="",Z8="",AA8="",AD8="",NOT(ISNUMBER(AE8)),NOT(ISNUMBER(AF8)),NOT(ISNUMBER(AG8))),"请补全必填",IF(OR(COUNTIF($B$5:$B$104,B8)>1,COUNTIF($C$5:$C$104,C8)>1),"ID重复",IF(COUNTIF('水晶主数据'!$B$5:$B$54,D8)=0,"关联不存在",IF(OR(ISNA(MATCH(F8,'_枚举'!$D$2:$D$7,0)),AND(L8<>"",ISNA(MATCH(L8,'_枚举'!$E$2:$E$6,0))),ISNA(MATCH(M8,'_枚举'!$A$2:$A$4,0)),ISNA(MATCH(N8,'_枚举'!$B$2:$B$5,0)),ISNA(MATCH(P8,'_枚举'!$F$2:$F$5,0)),ISNA(MATCH(Y8,'_枚举'!$C$2:$C$3,0)),ISNA(MATCH(Z8,'_枚举'!$C$2:$C$3,0)),ISNA(MATCH(AA8,'_枚举'!$C$2:$C$3,0)),ISNA(MATCH(AD8,'_枚举'!$G$2:$G$3,0))),"枚举错误",IF(OR(AND(G8<>"",OR(NOT(ISNUMBER(G8)),G8<=0)),AND(H8<>"",OR(NOT(ISNUMBER(H8)),H8<=0)),AND(I8<>"",OR(NOT(ISNUMBER(I8)),I8<=0)),AND(J8<>"",OR(NOT(ISNUMBER(J8)),J8<=0)),AND(K8<>"",OR(NOT(ISNUMBER(K8)),K8<=0)),NOT(ISNUMBER(Q8)),Q8<=0,AND(R8<>"",OR(NOT(ISNUMBER(R8)),R8<=0)),AND(S8<>"",OR(NOT(ISNUMBER(S8)),S8<=0)),NOT(ISNUMBER(T8)),T8<0,T8>1,NOT(ISNUMBER(AE8)),AE8<0,NOT(ISNUMBER(AF8)),AF8<0,NOT(ISNUMBER(AG8)),AG8<0,AND(AB8<>"",NOT(ISNUMBER(AB8)))),"格式错误",IF(AND(Z8="TRUE",OR(Y8<>"TRUE",M8="UNKNOWN")),"待人工复核","可导入"))))))) | B8: product-amethyst-faceted-8 | C8: AM-CNY-8 | D8: crystal-amethyst | E8: 紫水晶切面珠 8mm | F8: FACETED | G8: 8 | K8: 1 | L8: FACETED | M8: COMMERCIAL_A | N8: MARKET_DESCRIPTION | O8: 普通市场货，颜色和纹理存在自然差异，以当前批次实拍图为准。 | P8: PER_BEAD | Q8: 1 | T8: 0.03 | U8: crystal-amethyst-material-v1 | V8: sphere-faceted-8mm-v1 | W8: crystal-amethyst-texture-v1 | X8: amethyst-faceted-8.png | Y8: TRUE | Z8: TRUE | AA8: TRUE | AB8: 40 | AC8: 示例 | AD8: CNY | AE8: 680 | AF8: 285 | AG8: 100
A9: =IF(COUNTA(B9:AG9)=0,"待填写",IF(OR(B9="",C9="",D9="",E9="",F9="",AND(G9="",H9="",I9="",J9=""),M9="",N9="",P9="",NOT(ISNUMBER(Q9)),NOT(ISNUMBER(T9)),U9="",X9="",Y9="",Z9="",AA9="",AD9="",NOT(ISNUMBER(AE9)),NOT(ISNUMBER(AF9)),NOT(ISNUMBER(AG9))),"请补全必填",IF(OR(COUNTIF($B$5:$B$104,B9)>1,COUNTIF($C$5:$C$104,C9)>1),"ID重复",IF(COUNTIF('水晶主数据'!$B$5:$B$54,D9)=0,"关联不存在",IF(OR(ISNA(MATCH(F9,'_枚举'!$D$2:$D$7,0)),AND(L9<>"",ISNA(MATCH(L9,'_枚举'!$E$2:$E$6,0))),ISNA(MATCH(M9,'_枚举'!$A$2:$A$4,0)),ISNA(MATCH(N9,'_枚举'!$B$2:$B$5,0)),ISNA(MATCH(P9,'_枚举'!$F$2:$F$5,0)),ISNA(MATCH(Y9,'_枚举'!$C$2:$C$3,0)),ISNA(MATCH(Z9,'_枚举'!$C$2:$C$3,0)),ISNA(MATCH(AA9,'_枚举'!$C$2:$C$3,0)),ISNA(MATCH(AD9,'_枚举'!$G$2:$G$3,0))),"枚举错误",IF(OR(AND(G9<>"",OR(NOT(ISNUMBER(G9)),G9<=0)),AND(H9<>"",OR(NOT(ISNUMBER(H9)),H9<=0)),AND(I9<>"",OR(NOT(ISNUMBER(I9)),I9<=0)),AND(J9<>"",OR(NOT(ISNUMBER(J9)),J9<=0)),AND(K9<>"",OR(NOT(ISNUMBER(K9)),K9<=0)),NOT(ISNUMBER(Q9)),Q9<=0,AND(R9<>"",OR(NOT(ISNUMBER(R9)),R9<=0)),AND(S9<>"",OR(NOT(ISNUMBER(S9)),S9<=0)),NOT(ISNUMBER(T9)),T9<0,T9>1,NOT(ISNUMBER(AE9)),AE9<0,NOT(ISNUMBER(AF9)),AF9<0,NOT(ISNUMBER(AG9)),AG9<0,AND(AB9<>"",NOT(ISNUMBER(AB9)))),"格式错误",IF(AND(Z9="TRUE",OR(Y9<>"TRUE",M9="UNKNOWN")),"待人工复核","可导入"))))))) | B9: product-rose-quartz-round-8 | C9: RQ-CNY-8 | D9: crystal-rose-quartz | E9: 粉水晶圆珠 8mm | F9: ROUND | G9: 8 | K9: 1 | L9: NONE | M9: COMMERCIAL_A | N9: MARKET_DESCRIPTION | O9: 普通市场货，颜色和纹理存在自然差异，以当前批次实拍图为准。 | P9: PER_BEAD | Q9: 1 | T9: 0.03 | U9: crystal-rose-quartz-material-v1 | V9: sphere-round-8mm-v1 | W9: crystal-rose-quartz-texture-v1 | X9: rose-quartz-round-8.png | Y9: TRUE | Z9: TRUE | AA9: TRUE | AB9: 50 | AC9: 示例 | AD9: CNY | AE9: 360 | AF9: 151 | AG9: 100
A10: =IF(COUNTA(B10:AG10)=0,"待填写",IF(OR(B10="",C10="",D10="",E10="",F10="",AND(G10="",H10="",I10="",J10=""),M10="",N10="",P10="",NOT(ISNUMBER(Q10)),NOT(ISNUMBER(T10)),U10="",X10="",Y10="",Z10="",AA10="",AD10="",NOT(ISNUMBER(AE10)),NOT(ISNUMBER(AF10)),NOT(ISNUMBER(AG10))),"请补全必填",IF(OR(COUNTIF($B$5:$B$104,B10)>1,COUNTIF($C$5:$C$104,C10)>1),"ID重复",IF(COUNTIF('水晶主数据'!$B$5:$B$54,D10)=0,"关联不存在",IF(OR(ISNA(MATCH(F10,'_枚举'!$D$2:$D$7,0)),AND(L10<>"",ISNA(MATCH(L10,'_枚举'!$E$2:$E$6,0))),ISNA(MATCH(M10,'_枚举'!$A$2:$A$4,0)),ISNA(MATCH(N10,'_枚举'!$B$2:$B$5,0)),ISNA(MATCH(P10,'_枚举'!$F$2:$F$5,0)),ISNA(MATCH(Y10,'_枚举'!$C$2:$C$3,0)),ISNA(MATCH(Z10,'_枚举'!$C$2:$C$3,0)),ISNA(MATCH(AA10,'_枚举'!$C$2:$C$3,0)),ISNA(MATCH(AD10,'_枚举'!$G$2:$G$3,0))),"枚举错误",IF(OR(AND(G10<>"",OR(NOT(ISNUMBER(G10)),G10<=0)),AND(H10<>"",OR(NOT(ISNUMBER(H10)),H10<=0)),AND(I10<>"",OR(NOT(ISNUMBER(I10)),I10<=0)),AND(J10<>"",OR(NOT(ISNUMBER(J10)),J10<=0)),AND(K10<>"",OR(NOT(ISNUMBER(K10)),K10<=0)),NOT(ISNUMBER(Q10)),Q10<=0,AND(R10<>"",OR(NOT(ISNUMBER(R10)),R10<=0)),AND(S10<>"",OR(NOT(ISNUMBER(S10)),S10<=0)),NOT(ISNUMBER(T10)),T10<0,T10>1,NOT(ISNUMBER(AE10)),AE10<0,NOT(ISNUMBER(AF10)),AF10<0,NOT(ISNUMBER(AG10)),AG10<0,AND(AB10<>"",NOT(ISNUMBER(AB10)))),"格式错误",IF(AND(Z10="TRUE",OR(Y10<>"TRUE",M10="UNKNOWN")),"待人工复核","可导入")))))))
A11: =IF(COUNTA(B11:AG11)=0,"待填写",IF(OR(B11="",C11="",D11="",E11="",F11="",AND(G11="",H11="",I11="",J11=""),M11="",N11="",P11="",NOT(ISNUMBER(Q11)),NOT(ISNUMBER(T11)),U11="",X11="",Y11="",Z11="",AA11="",AD11="",NOT(ISNUMBER(AE11)),NOT(ISNUMBER(AF11)),NOT(ISNUMBER(AG11))),"请补全必填",IF(OR(COUNTIF($B$5:$B$104,B11)>1,COUNTIF($C$5:$C$104,C11)>1),"ID重复",IF(COUNTIF('水晶主数据'!$B$5:$B$54,D11)=0,"关联不存在",IF(OR(ISNA(MATCH(F11,'_枚举'!$D$2:$D$7,0)),AND(L11<>"",ISNA(MATCH(L11,'_枚举'!$E$2:$E$6,0))),ISNA(MATCH(M11,'_枚举'!$A$2:$A$4,0)),ISNA(MATCH(N11,'_枚举'!$B$2:$B$5,0)),ISNA(MATCH(P11,'_枚举'!$F$2:$F$5,0)),ISNA(MATCH(Y11,'_枚举'!$C$2:$C$3,0)),ISNA(MATCH(Z11,'_枚举'!$C$2:$C$3,0)),ISNA(MATCH(AA11,'_枚举'!$C$2:$C$3,0)),ISNA(MATCH(AD11,'_枚举'!$G$2:$G$3,0))),"枚举错误",IF(OR(AND(G11<>"",OR(NOT(ISNUMBER(G11)),G11<=0)),AND(H11<>"",OR(NOT(ISNUMBER(H11)),H11<=0)),AND(I11<>"",OR(NOT(ISNUMBER(I11)),I11<=0)),AND(J11<>"",OR(NOT(ISNUMBER(J11)),J11<=0)),AND(K11<>"",OR(NOT(ISNUMBER(K11)),K11<=0)),NOT(ISNUMBER(Q11)),Q11<=0,AND(R11<>"",OR(NOT(ISNUMBER(R11)),R11<=0)),AND(S11<>"",OR(NOT(ISNUMBER(S11)),S11<=0)),NOT(ISNUMBER(T11)),T11<0,T11>1,NOT(ISNUMBER(AE11)),AE11<0,NOT(ISNUMBER(AF11)),AF11<0,NOT(ISNUMBER(AG11)),AG11<0,AND(AB11<>"",NOT(ISNUMBER(AB11)))),"格式错误",IF(AND(Z11="TRUE",OR(Y11<>"TRUE",M11="UNKNOWN")),"待人工复核","可导入")))))))
A12: =IF(COUNTA(B12:AG12)=0,"待填写",IF(OR(B12="",C12="",D12="",E12="",F12="",AND(G12="",H12="",I12="",J12=""),M12="",N12="",P12="",NOT(ISNUMBER(Q12)),NOT(ISNUMBER(T12)),U12="",X12="",Y12="",Z12="",AA12="",AD12="",NOT(ISNUMBER(AE12)),NOT(ISNUMBER(AF12)),NOT(ISNUMBER(AG12))),"请补全必填",IF(OR(COUNTIF($B$5:$B$104,B12)>1,COUNTIF($C$5:$C$104,C12)>1),"ID重复",IF(COUNTIF('水晶主数据'!$B$5:$B$54,D12)=0,"关联不存在",IF(OR(ISNA(MATCH(F12,'_枚举'!$D$2:$D$7,0)),AND(L12<>"",ISNA(MATCH(L12,'_枚举'!$E$2:$E$6,0))),ISNA(MATCH(M12,'_枚举'!$A$2:$A$4,0)),ISNA(MATCH(N12,'_枚举'!$B$2:$B$5,0)),ISNA(MATCH(P12,'_枚举'!$F$2:$F$5,0)),ISNA(MATCH(Y12,'_枚举'!$C$2:$C$3,0)),ISNA(MATCH(Z12,'_枚举'!$C$2:$C$3,0)),ISNA(MATCH(AA12,'_枚举'!$C$2:$C$3,0)),ISNA(MATCH(AD12,'_枚举'!$G$2:$G$3,0))),"枚举错误",IF(OR(AND(G12<>"",OR(NOT(ISNUMBER(G12)),G12<=0)),AND(H12<>"",OR(NOT(ISNUMBER(H12)),H12<=0)),AND(I12<>"",OR(NOT(ISNUMBER(I12)),I12<=0)),AND(J12<>"",OR(NOT(ISNUMBER(J12)),J12<=0)),AND(K12<>"",OR(NOT(ISNUMBER(K12)),K12<=0)),NOT(ISNUMBER(Q12)),Q12<=0,AND(R12<>"",OR(NOT(ISNUMBER(R12)),R12<=0)),AND(S12<>"",OR(NOT(ISNUMBER(S12)),S12<=0)),NOT(ISNUMBER(T12)),T12<0,T12>1,NOT(ISNUMBER(AE12)),AE12<0,NOT(ISNUMBER(AF12)),AF12<0,NOT(ISNUMBER(AG12)),AG12<0,AND(AB12<>"",NOT(ISNUMBER(AB12)))),"格式错误",IF(AND(Z12="TRUE",OR(Y12<>"TRUE",M12="UNKNOWN")),"待人工复核","可导入")))))))
A13: =IF(COUNTA(B13:AG13)=0,"待填写",IF(OR(B13="",C13="",D13="",E13="",F13="",AND(G13="",H13="",I13="",J13=""),M13="",N13="",P13="",NOT(ISNUMBER(Q13)),NOT(ISNUMBER(T13)),U13="",X13="",Y13="",Z13="",AA13="",AD13="",NOT(ISNUMBER(AE13)),NOT(ISNUMBER(AF13)),NOT(ISNUMBER(AG13))),"请补全必填",IF(OR(COUNTIF($B$5:$B$104,B13)>1,COUNTIF($C$5:$C$104,C13)>1),"ID重复",IF(COUNTIF('水晶主数据'!$B$5:$B$54,D13)=0,"关联不存在",IF(OR(ISNA(MATCH(F13,'_枚举'!$D$2:$D$7,0)),AND(L13<>"",ISNA(MATCH(L13,'_枚举'!$E$2:$E$6,0))),ISNA(MATCH(M13,'_枚举'!$A$2:$A$4,0)),ISNA(MATCH(N13,'_枚举'!$B$2:$B$5,0)),ISNA(MATCH(P13,'_枚举'!$F$2:$F$5,0)),ISNA(MATCH(Y13,'_枚举'!$C$2:$C$3,0)),ISNA(MATCH(Z13,'_枚举'!$C$2:$C$3,0)),ISNA(MATCH(AA13,'_枚举'!$C$2:$C$3,0)),ISNA(MATCH(AD13,'_枚举'!$G$2:$G$3,0))),"枚举错误",IF(OR(AND(G13<>"",OR(NOT(ISNUMBER(G13)),G13<=0)),AND(H13<>"",OR(NOT(ISNUMBER(H13)),H13<=0)),AND(I13<>"",OR(NOT(ISNUMBER(I13)),I13<=0)),AND(J13<>"",OR(NOT(ISNUMBER(J13)),J13<=0)),AND(K13<>"",OR(NOT(ISNUMBER(K13)),K13<=0)),NOT(ISNUMBER(Q13)),Q13<=0,AND(R13<>"",OR(NOT(ISNUMBER(R13)),R13<=0)),AND(S13<>"",OR(NOT(ISNUMBER(S13)),S13<=0)),NOT(ISNUMBER(T13)),T13<0,T13>1,NOT(ISNUMBER(AE13)),AE13<0,NOT(ISNUMBER(AF13)),AF13<0,NOT(ISNUMBER(AG13)),AG13<0,AND(AB13<>"",NOT(ISNUMBER(AB13)))),"格式错误",IF(AND(Z13="TRUE",OR(Y13<>"TRUE",M13="UNKNOWN")),"待人工复核","可导入")))))))
A14: =IF(COUNTA(B14:AG14)=0,"待填写",IF(OR(B14="",C14="",D14="",E14="",F14="",AND(G14="",H14="",I14="",J14=""),M14="",N14="",P14="",NOT(ISNUMBER(Q14)),NOT(ISNUMBER(T14)),U14="",X14="",Y14="",Z14="",AA14="",AD14="",NOT(ISNUMBER(AE14)),NOT(ISNUMBER(AF14)),NOT(ISNUMBER(AG14))),"请补全必填",IF(OR(COUNTIF($B$5:$B$104,B14)>1,COUNTIF($C$5:$C$104,C14)>1),"ID重复",IF(COUNTIF('水晶主数据'!$B$5:$B$54,D14)=0,"关联不存在",IF(OR(ISNA(MATCH(F14,'_枚举'!$D$2:$D$7,0)),AND(L14<>"",ISNA(MATCH(L14,'_枚举'!$E$2:$E$6,0))),ISNA(MATCH(M14,'_枚举'!$A$2:$A$4,0)),ISNA(MATCH(N14,'_枚举'!$B$2:$B$5,0)),ISNA(MATCH(P14,'_枚举'!$F$2:$F$5,0)),ISNA(MATCH(Y14,'_枚举'!$C$2:$C$3,0)),ISNA(MATCH(Z14,'_枚举'!$C$2:$C$3,0)),ISNA(MATCH(AA14,'_枚举'!$C$2:$C$3,0)),ISNA(MATCH(AD14,'_枚举'!$G$2:$G$3,0))),"枚举错误",IF(OR(AND(G14<>"",OR(NOT(ISNUMBER(G14)),G14<=0)),AND(H14<>"",OR(NOT(ISNUMBER(H14)),H14<=0)),AND(I14<>"",OR(NOT(ISNUMBER(I14)),I14<=0)),AND(J14<>"",OR(NOT(ISNUMBER(J14)),J14<=0)),AND(K14<>"",OR(NOT(ISNUMBER(K14)),K14<=0)),NOT(ISNUMBER(Q14)),Q14<=0,AND(R14<>"",OR(NOT(ISNUMBER(R14)),R14<=0)),AND(S14<>"",OR(NOT(ISNUMBER(S14)),S14<=0)),NOT(ISNUMBER(T14)),T14<0,T14>1,NOT(ISNUMBER(AE14)),AE14<0,NOT(ISNUMBER(AF14)),AF14<0,NOT(ISNUMBER(AG14)),AG14<0,AND(AB14<>"",NOT(ISNUMBER(AB14)))),"格式错误",IF(AND(Z14="TRUE",OR(Y14<>"TRUE",M14="UNKNOWN")),"待人工复核","可导入")))))))
A15: =IF(COUNTA(B15:AG15)=0,"待填写",IF(OR(B15="",C15="",D15="",E15="",F15="",AND(G15="",H15="",I15="",J15=""),M15="",N15="",P15="",NOT(ISNUMBER(Q15)),NOT(ISNUMBER(T15)),U15="",X15="",Y15="",Z15="",AA15="",AD15="",NOT(ISNUMBER(AE15)),NOT(ISNUMBER(AF15)),NOT(ISNUMBER(AG15))),"请补全必填",IF(OR(COUNTIF($B$5:$B$104,B15)>1,COUNTIF($C$5:$C$104,C15)>1),"ID重复",IF(COUNTIF('水晶主数据'!$B$5:$B$54,D15)=0,"关联不存在",IF(OR(ISNA(MATCH(F15,'_枚举'!$D$2:$D$7,0)),AND(L15<>"",ISNA(MATCH(L15,'_枚举'!$E$2:$E$6,0))),ISNA(MATCH(M15,'_枚举'!$A$2:$A$4,0)),ISNA(MATCH(N15,'_枚举'!$B$2:$B$5,0)),ISNA(MATCH(P15,'_枚举'!$F$2:$F$5,0)),ISNA(MATCH(Y15,'_枚举'!$C$2:$C$3,0)),ISNA(MATCH(Z15,'_枚举'!$C$2:$C$3,0)),ISNA(MATCH(AA15,'_枚举'!$C$2:$C$3,0)),ISNA(MATCH(AD15,'_枚举'!$G$2:$G$3,0))),"枚举错误",IF(OR(AND(G15<>"",OR(NOT(ISNUMBER(G15)),G15<=0)),AND(H15<>"",OR(NOT(ISNUMBER(H15)),H15<=0)),AND(I15<>"",OR(NOT(ISNUMBER(I15)),I15<=0)),AND(J15<>"",OR(NOT(ISNUMBER(J15)),J15<=0)),AND(K15<>"",OR(NOT(ISNUMBER(K15)),K15<=0)),NOT(ISNUMBER(Q15)),Q15<=0,AND(R15<>"",OR(NOT(ISNUMBER(R15)),R15<=0)),AND(S15<>"",OR(NOT(ISNUMBER(S15)),S15<=0)),NOT(ISNUMBER(T15)),T15<0,T15>1,NOT(ISNUMBER(AE15)),AE15<0,NOT(ISNUMBER(AF15)),AF15<0,NOT(ISNUMBER(AG15)),AG15<0,AND(AB15<>"",NOT(ISNUMBER(AB15)))),"格式错误",IF(AND(Z15="TRUE",OR(Y15<>"TRUE",M15="UNKNOWN")),"待人工复核","可导入")))))))
A16: =IF(COUNTA(B16:AG16)=0,"待填写",IF(OR(B16="",C16="",D16="",E16="",F16="",AND(G16="",H16="",I16="",J16=""),M16="",N16="",P16="",NOT(ISNUMBER(Q16)),NOT(ISNUMBER(T16)),U16="",X16="",Y16="",Z16="",AA16="",AD16="",NOT(ISNUMBER(AE16)),NOT(ISNUMBER(AF16)),NOT(ISNUMBER(AG16))),"请补全必填",IF(OR(COUNTIF($B$5:$B$104,B16)>1,COUNTIF($C$5:$C$104,C16)>1),"ID重复",IF(COUNTIF('水晶主数据'!$B$5:$B$54,D16)=0,"关联不存在",IF(OR(ISNA(MATCH(F16,'_枚举'!$D$2:$D$7,0)),AND(L16<>"",ISNA(MATCH(L16,'_枚举'!$E$2:$E$6,0))),ISNA(MATCH(M16,'_枚举'!$A$2:$A$4,0)),ISNA(MATCH(N16,'_枚举'!$B$2:$B$5,0)),ISNA(MATCH(P16,'_枚举'!$F$2:$F$5,0)),ISNA(MATCH(Y16,'_枚举'!$C$2:$C$3,0)),ISNA(MATCH(Z16,'_枚举'!$C$2:$C$3,0)),ISNA(MATCH(AA16,'_枚举'!$C$2:$C$3,0)),ISNA(MATCH(AD16,'_枚举'!$G$2:$G$3,0))),"枚举错误",IF(OR(AND(G16<>"",OR(NOT(ISNUMBER(G16)),G16<=0)),AND(H16<>"",OR(NOT(ISNUMBER(H16)),H16<=0)),AND(I16<>"",OR(NOT(ISNUMBER(I16)),I16<=0)),AND(J16<>"",OR(NOT(ISNUMBER(J16)),J16<=0)),AND(K16<>"",OR(NOT(ISNUMBER(K16)),K16<=0)),NOT(ISNUMBER(Q16)),Q16<=0,AND(R16<>"",OR(NOT(ISNUMBER(R16)),R16<=0)),AND(S16<>"",OR(NOT(ISNUMBER(S16)),S16<=0)),NOT(ISNUMBER(T16)),T16<0,T16>1,NOT(ISNUMBER(AE16)),AE16<0,NOT(ISNUMBER(AF16)),AF16<0,NOT(ISNUMBER(AG16)),AG16<0,AND(AB16<>"",NOT(ISNUMBER(AB16)))),"格式错误",IF(AND(Z16="TRUE",OR(Y16<>"TRUE",M16="UNKNOWN")),"待人工复核","可导入")))))))
A17: =IF(COUNTA(B17:AG17)=0,"待填写",IF(OR(B17="",C17="",D17="",E17="",F17="",AND(G17="",H17="",I17="",J17=""),M17="",N17="",P17="",NOT(ISNUMBER(Q17)),NOT(ISNUMBER(T17)),U17="",X17="",Y17="",Z17="",AA17="",AD17="",NOT(ISNUMBER(AE17)),NOT(ISNUMBER(AF17)),NOT(ISNUMBER(AG17))),"请补全必填",IF(OR(COUNTIF($B$5:$B$104,B17)>1,COUNTIF($C$5:$C$104,C17)>1),"ID重复",IF(COUNTIF('水晶主数据'!$B$5:$B$54,D17)=0,"关联不存在",IF(OR(ISNA(MATCH(F17,'_枚举'!$D$2:$D$7,0)),AND(L17<>"",ISNA(MATCH(L17,'_枚举'!$E$2:$E$6,0))),ISNA(MATCH(M17,'_枚举'!$A$2:$A$4,0)),ISNA(MATCH(N17,'_枚举'!$B$2:$B$5,0)),ISNA(MATCH(P17,'_枚举'!$F$2:$F$5,0)),ISNA(MATCH(Y17,'_枚举'!$C$2:$C$3,0)),ISNA(MATCH(Z17,'_枚举'!$C$2:$C$3,0)),ISNA(MATCH(AA17,'_枚举'!$C$2:$C$3,0)),ISNA(MATCH(AD17,'_枚举'!$G$2:$G$3,0))),"枚举错误",IF(OR(AND(G17<>"",OR(NOT(ISNUMBER(G17)),G17<=0)),AND(H17<>"",OR(NOT(ISNUMBER(H17)),H17<=0)),AND(I17<>"",OR(NOT(ISNUMBER(I17)),I17<=0)),AND(J17<>"",OR(NOT(ISNUMBER(J17)),J17<=0)),AND(K17<>"",OR(NOT(ISNUMBER(K17)),K17<=0)),NOT(ISNUMBER(Q17)),Q17<=0,AND(R17<>"",OR(NOT(ISNUMBER(R17)),R17<=0)),AND(S17<>"",OR(NOT(ISNUMBER(S17)),S17<=0)),NOT(ISNUMBER(T17)),T17<0,T17>1,NOT(ISNUMBER(AE17)),AE17<0,NOT(ISNUMBER(AF17)),AF17<0,NOT(ISNUMBER(AG17)),AG17<0,AND(AB17<>"",NOT(ISNUMBER(AB17)))),"格式错误",IF(AND(Z17="TRUE",OR(Y17<>"TRUE",M17="UNKNOWN")),"待人工复核","可导入")))))))
A18: =IF(COUNTA(B18:AG18)=0,"待填写",IF(OR(B18="",C18="",D18="",E18="",F18="",AND(G18="",H18="",I18="",J18=""),M18="",N18="",P18="",NOT(ISNUMBER(Q18)),NOT(ISNUMBER(T18)),U18="",X18="",Y18="",Z18="",AA18="",AD18="",NOT(ISNUMBER(AE18)),NOT(ISNUMBER(AF18)),NOT(ISNUMBER(AG18))),"请补全必填",IF(OR(COUNTIF($B$5:$B$104,B18)>1,COUNTIF($C$5:$C$104,C18)>1),"ID重复",IF(COUNTIF('水晶主数据'!$B$5:$B$54,D18)=0,"关联不存在",IF(OR(ISNA(MATCH(F18,'_枚举'!$D$2:$D$7,0)),AND(L18<>"",ISNA(MATCH(L18,'_枚举'!$E$2:$E$6,0))),ISNA(MATCH(M18,'_枚举'!$A$2:$A$4,0)),ISNA(MATCH(N18,'_枚举'!$B$2:$B$5,0)),ISNA(MATCH(P18,'_枚举'!$F$2:$F$5,0)),ISNA(MATCH(Y18,'_枚举'!$C$2:$C$3,0)),ISNA(MATCH(Z18,'_枚举'!$C$2:$C$3,0)),ISNA(MATCH(AA18,'_枚举'!$C$2:$C$3,0)),ISNA(MATCH(AD18,'_枚举'!$G$2:$G$3,0))),"枚举错误",IF(OR(AND(G18<>"",OR(NOT(ISNUMBER(G18)),G18<=0)),AND(H18<>"",OR(NOT(ISNUMBER(H18)),H18<=0)),AND(I18<>"",OR(NOT(ISNUMBER(I18)),I18<=0)),AND(J18<>"",OR(NOT(ISNUMBER(J18)),J18<=0)),AND(K18<>"",OR(NOT(ISNUMBER(K18)),K18<=0)),NOT(ISNUMBER(Q18)),Q18<=0,AND(R18<>"",OR(NOT(ISNUMBER(R18)),R18<=0)),AND(S18<>"",OR(NOT(ISNUMBER(S18)),S18<=0)),NOT(ISNUMBER(T18)),T18<0,T18>1,NOT(ISNUMBER(AE18)),AE18<0,NOT(ISNUMBER(AF18)),AF18<0,NOT(ISNUMBER(AG18)),AG18<0,AND(AB18<>"",NOT(ISNUMBER(AB18)))),"格式错误",IF(AND(Z18="TRUE",OR(Y18<>"TRUE",M18="UNKNOWN")),"待人工复核","可导入")))))))
A19: =IF(COUNTA(B19:AG19)=0,"待填写",IF(OR(B19="",C19="",D19="",E19="",F19="",AND(G19="",H19="",I19="",J19=""),M19="",N19="",P19="",NOT(ISNUMBER(Q19)),NOT(ISNUMBER(T19)),U19="",X19="",Y19="",Z19="",AA19="",AD19="",NOT(ISNUMBER(AE19)),NOT(ISNUMBER(AF19)),NOT(ISNUMBER(AG19))),"请补全必填",IF(OR(COUNTIF($B$5:$B$104,B19)>1,COUNTIF($C$5:$C$104,C19)>1),"ID重复",IF(COUNTIF('水晶主数据'!$B$5:$B$54,D19)=0,"关联不存在",IF(OR(ISNA(MATCH(F19,'_枚举'!$D$2:$D$7,0)),AND(L19<>"",ISNA(MATCH(L19,'_枚举'!$E$2:$E$6,0))),ISNA(MATCH(M19,'_枚举'!$A$2:$A$4,0)),ISNA(MATCH(N19,'_枚举'!$B$2:$B$5,0)),ISNA(MATCH(P19,'_枚举'!$F$2:$F$5,0)),ISNA(MATCH(Y19,'_枚举'!$C$2:$C$3,0)),ISNA(MATCH(Z19,'_枚举'!$C$2:$C$3,0)),ISNA(MATCH(AA19,'_枚举'!$C$2:$C$3,0)),ISNA(MATCH(AD19,'_枚举'!$G$2:$G$3,0))),"枚举错误",IF(OR(AND(G19<>"",OR(NOT(ISNUMBER(G19)),G19<=0)),AND(H19<>"",OR(NOT(ISNUMBER(H19)),H19<=0)),AND(I19<>"",OR(NOT(ISNUMBER(I19)),I19<=0)),AND(J19<>"",OR(NOT(ISNUMBER(J19)),J19<=0)),AND(K19<>"",OR(NOT(ISNUMBER(K19)),K19<=0)),NOT(ISNUMBER(Q19)),Q19<=0,AND(R19<>"",OR(NOT(ISNUMBER(R19)),R19<=0)),AND(S19<>"",OR(NOT(ISNUMBER(S19)),S19<=0)),NOT(ISNUMBER(T19)),T19<0,T19>1,NOT(ISNUMBER(AE19)),AE19<0,NOT(ISNUMBER(AF19)),AF19<0,NOT(ISNUMBER(AG19)),AG19<0,AND(AB19<>"",NOT(ISNUMBER(AB19)))),"格式错误",IF(AND(Z19="TRUE",OR(Y19<>"TRUE",M19="UNKNOWN")),"待人工复核","可导入")))))))
A20: =IF(COUNTA(B20:AG20)=0,"待填写",IF(OR(B20="",C20="",D20="",E20="",F20="",AND(G20="",H20="",I20="",J20=""),M20="",N20="",P20="",NOT(ISNUMBER(Q20)),NOT(ISNUMBER(T20)),U20="",X20="",Y20="",Z20="",AA20="",AD20="",NOT(ISNUMBER(AE20)),NOT(ISNUMBER(AF20)),NOT(ISNUMBER(AG20))),"请补全必填",IF(OR(COUNTIF($B$5:$B$104,B20)>1,COUNTIF($C$5:$C$104,C20)>1),"ID重复",IF(COUNTIF('水晶主数据'!$B$5:$B$54,D20)=0,"关联不存在",IF(OR(ISNA(MATCH(F20,'_枚举'!$D$2:$D$7,0)),AND(L20<>"",ISNA(MATCH(L20,'_枚举'!$E$2:$E$6,0))),ISNA(MATCH(M20,'_枚举'!$A$2:$A$4,0)),ISNA(MATCH(N20,'_枚举'!$B$2:$B$5,0)),ISNA(MATCH(P20,'_枚举'!$F$2:$F$5,0)),ISNA(MATCH(Y20,'_枚举'!$C$2:$C$3,0)),ISNA(MATCH(Z20,'_枚举'!$C$2:$C$3,0)),ISNA(MATCH(AA20,'_枚举'!$C$2:$C$3,0)),ISNA(MATCH(AD20,'_枚举'!$G$2:$G$3,0))),"枚举错误",IF(OR(AND(G20<>"",OR(NOT(ISNUMBER(G20)),G20<=0)),AND(H20<>"",OR(NOT(ISNUMBER(H20)),H20<=0)),AND(I20<>"",OR(NOT(ISNUMBER(I20)),I20<=0)),AND(J20<>"",OR(NOT(ISNUMBER(J20)),J20<=0)),AND(K20<>"",OR(NOT(ISNUMBER(K20)),K20<=0)),NOT(ISNUMBER(Q20)),Q20<=0,AND(R20<>"",OR(NOT(ISNUMBER(R20)),R20<=0)),AND(S20<>"",OR(NOT(ISNUMBER(S20)),S20<=0)),NOT(ISNUMBER(T20)),T20<0,T20>1,NOT(ISNUMBER(AE20)),AE20<0,NOT(ISNUMBER(AF20)),AF20<0,NOT(ISNUMBER(AG20)),AG20<0,AND(AB20<>"",NOT(ISNUMBER(AB20)))),"格式错误",IF(AND(Z20="TRUE",OR(Y20<>"TRUE",M20="UNKNOWN")),"待人工复核","可导入")))))))
A21: =IF(COUNTA(B21:AG21)=0,"待填写",IF(OR(B21="",C21="",D21="",E21="",F21="",AND(G21="",H21="",I21="",J21=""),M21="",N21="",P21="",NOT(ISNUMBER(Q21)),NOT(ISNUMBER(T21)),U21="",X21="",Y21="",Z21="",AA21="",AD21="",NOT(ISNUMBER(AE21)),NOT(ISNUMBER(AF21)),NOT(ISNUMBER(AG21))),"请补全必填",IF(OR(COUNTIF($B$5:$B$104,B21)>1,COUNTIF($C$5:$C$104,C21)>1),"ID重复",IF(COUNTIF('水晶主数据'!$B$5:$B$54,D21)=0,"关联不存在",IF(OR(ISNA(MATCH(F21,'_枚举'!$D$2:$D$7,0)),AND(L21<>"",ISNA(MATCH(L21,'_枚举'!$E$2:$E$6,0))),ISNA(MATCH(M21,'_枚举'!$A$2:$A$4,0)),ISNA(MATCH(N21,'_枚举'!$B$2:$B$5,0)),ISNA(MATCH(P21,'_枚举'!$F$2:$F$5,0)),ISNA(MATCH(Y21,'_枚举'!$C$2:$C$3,0)),ISNA(MATCH(Z21,'_枚举'!$C$2:$C$3,0)),ISNA(MATCH(AA21,'_枚举'!$C$2:$C$3,0)),ISNA(MATCH(AD21,'_枚举'!$G$2:$G$3,0))),"枚举错误",IF(OR(AND(G21<>"",OR(NOT(ISNUMBER(G21)),G21<=0)),AND(H21<>"",OR(NOT(ISNUMBER(H21)),H21<=0)),AND(I21<>"",OR(NOT(ISNUMBER(I21)),I21<=0)),AND(J21<>"",OR(NOT(ISNUMBER(J21)),J21<=0)),AND(K21<>"",OR(NOT(ISNUMBER(K21)),K21<=0)),NOT(ISNUMBER(Q21)),Q21<=0,AND(R21<>"",OR(NOT(ISNUMBER(R21)),R21<=0)),AND(S21<>"",OR(NOT(ISNUMBER(S21)),S21<=0)),NOT(ISNUMBER(T21)),T21<0,T21>1,NOT(ISNUMBER(AE21)),AE21<0,NOT(ISNUMBER(AF21)),AF21<0,NOT(ISNUMBER(AG21)),AG21<0,AND(AB21<>"",NOT(ISNUMBER(AB21)))),"格式错误",IF(AND(Z21="TRUE",OR(Y21<>"TRUE",M21="UNKNOWN")),"待人工复核","可导入")))))))
... A104: =IF(COUNTA(B104:AG104)=0,"待填写",IF(OR(B104="",C104="",D104="",E104="",F104="",AND(G104="",H104="",I104="",J104=""),M104="",N104="",P104="",NOT(ISNUMBER(Q104)),NOT(ISNUMBER(T104)),U104="",X104="",Y104="",Z104="",AA104="",AD104="",NOT(ISNUMBER(AE104)),NOT(ISNUMBER(AF104)),NOT(ISNUMBER(AG104))),"请补全必填",IF(OR(COUNTIF($B$5:$B$104,B104)>1,COUNTIF($C$5:$C$104,C104)>1),"ID重复",IF(COUNTIF('水晶主数据'!$B$5:$B$54,D104)=0,"关联不存在",IF(OR(ISNA(MATCH(F104,'_枚举'!$D$2:$D$7,0)),AND(L104<>"",ISNA(MATCH(L104,'_枚举'!$E$2:$E$6,0))),ISNA(MATCH(M104,'_枚举'!$A$2:$A$4,0)),ISNA(MATCH(N104,'_枚举'!$B$2:$B$5,0)),ISNA(MATCH(P104,'_枚举'!$F$2:$F$5,0)),ISNA(MATCH(Y104,'_枚举'!$C$2:$C$3,0)),ISNA(MATCH(Z104,'_枚举'!$C$2:$C$3,0)),ISNA(MATCH(AA104,'_枚举'!$C$2:$C$3,0)),ISNA(MATCH(AD104,'_枚举'!$G$2:$G$3,0))),"枚举错误",IF(OR(AND(G104<>"",OR(NOT(ISNUMBER(G104)),G104<=0)),AND(H104<>"",OR(NOT(ISNUMBER(H104)),H104<=0)),AND(I104<>"",OR(NOT(ISNUMBER(I104)),I104<=0)),AND(J104<>"",OR(NOT(ISNUMBER(J104)),J104<=0)),AND(K104<>"",OR(NOT(ISNUMBER(K104)),K104<=0)),NOT(ISNUMBER(Q104)),Q104<=0,AND(R104<>"",OR(NOT(ISNUMBER(R104)),R104<=0)),AND(S104<>"",OR(NOT(ISNUMBER(S104)),S104<=0)),NOT(ISNUMBER(T104)),T104<0,T104>1,NOT(ISNUMBER(AE104)),AE104<0,NOT(ISNUMBER(AF104)),AF104<0,NOT(ISNUMBER(AG104)),AG104<0,AND(AB104<>"",NOT(ISNUMBER(AB104)))),"格式错误",IF(AND(Z104="TRUE",OR(Y104<>"TRUE",M104="UNKNOWN")),"待人工复核","可导入")))))))

Sheet 配件SKU
A1: 配件 SKU｜隔珠、吊坠、跑环等
A4: 导入状态 | B4: product_id* | C4: sku* | D4: 配件类型* | E4: 材质* | F4: 表面处理* | G4: 直径_mm | H4: 宽度_mm | I4: 高度_mm | J4: 深度_mm | K4: 币种* | L4: 售价_最小单位* | M4: 成本_最小单位* | N4: model_asset_key | O4: texture_asset_key | P4: 商品图片文件名* | Q4: 可用库存* | R4: 是否上架*
A5: =IF(COUNTA(B5:R5)=0,"待填写",IF(OR(B5="",C5="",D5="",E5="",F5="",K5="",NOT(ISNUMBER(L5)),NOT(ISNUMBER(M5)),P5="",NOT(ISNUMBER(Q5)),R5=""),"请补全必填",IF(OR(COUNTIF($B$5:$B$54,B5)>1,COUNTIF($C$5:$C$54,C5)>1),"ID重复",IF(OR(ISNA(MATCH(D5,'_枚举'!$Q$2:$Q$7,0)),ISNA(MATCH(E5,'_枚举'!$R$2:$R$7,0)),ISNA(MATCH(F5,'_枚举'!$S$2:$S$6,0)),ISNA(MATCH(K5,'_枚举'!$G$2:$G$3,0)),ISNA(MATCH(R5,'_枚举'!$C$2:$C$3,0))),"枚举错误",IF(OR(NOT(ISNUMBER(L5)),L5<0,NOT(ISNUMBER(M5)),M5<0,NOT(ISNUMBER(Q5)),Q5<0,AND(G5<>"",OR(NOT(ISNUMBER(G5)),G5<=0)),AND(H5<>"",OR(NOT(ISNUMBER(H5)),H5<=0)),AND(I5<>"",OR(NOT(ISNUMBER(I5)),I5<=0)),AND(J5<>"",OR(NOT(ISNUMBER(J5)),J5<=0))),"格式错误","可导入"))))) | B5: product-spacer-silver-3 | C5: SP-CNY-SILVER-3 | D5: SPACER | E5: STERLING_SILVER | F5: POLISHED | G5: 3 | H5: 2 | K5: CNY | L5: 300 | M5: 110 | N5: spacer-silver-3mm-v1 | P5: spacer-silver-3.png | Q5: 100 | R5: TRUE
A6: =IF(COUNTA(B6:R6)=0,"待填写",IF(OR(B6="",C6="",D6="",E6="",F6="",K6="",NOT(ISNUMBER(L6)),NOT(ISNUMBER(M6)),P6="",NOT(ISNUMBER(Q6)),R6=""),"请补全必填",IF(OR(COUNTIF($B$5:$B$54,B6)>1,COUNTIF($C$5:$C$54,C6)>1),"ID重复",IF(OR(ISNA(MATCH(D6,'_枚举'!$Q$2:$Q$7,0)),ISNA(MATCH(E6,'_枚举'!$R$2:$R$7,0)),ISNA(MATCH(F6,'_枚举'!$S$2:$S$6,0)),ISNA(MATCH(K6,'_枚举'!$G$2:$G$3,0)),ISNA(MATCH(R6,'_枚举'!$C$2:$C$3,0))),"枚举错误",IF(OR(NOT(ISNUMBER(L6)),L6<0,NOT(ISNUMBER(M6)),M6<0,NOT(ISNUMBER(Q6)),Q6<0,AND(G6<>"",OR(NOT(ISNUMBER(G6)),G6<=0)),AND(H6<>"",OR(NOT(ISNUMBER(H6)),H6<=0)),AND(I6<>"",OR(NOT(ISNUMBER(I6)),I6<=0)),AND(J6<>"",OR(NOT(ISNUMBER(J6)),J6<=0))),"格式错误","可导入"))))) | B6: product-pendant-drop-silver-8 | C6: PD-CNY-SILVER-8 | D6: PENDANT | E6: STERLING_SILVER | F6: POLISHED | H6: 5 | I6: 8 | J6: 2 | K6: CNY | L6: 500 | M6: 180 | N6: pendant-drop-silver-8mm-v1 | P6: pendant-drop-silver-8.png | Q6: 100 | R6: TRUE
A7: =IF(COUNTA(B7:R7)=0,"待填写",IF(OR(B7="",C7="",D7="",E7="",F7="",K7="",NOT(ISNUMBER(L7)),NOT(ISNUMBER(M7)),P7="",NOT(ISNUMBER(Q7)),R7=""),"请补全必填",IF(OR(COUNTIF($B$5:$B$54,B7)>1,COUNTIF($C$5:$C$54,C7)>1),"ID重复",IF(OR(ISNA(MATCH(D7,'_枚举'!$Q$2:$Q$7,0)),ISNA(MATCH(E7,'_枚举'!$R$2:$R$7,0)),ISNA(MATCH(F7,'_枚举'!$S$2:$S$6,0)),ISNA(MATCH(K7,'_枚举'!$G$2:$G$3,0)),ISNA(MATCH(R7,'_枚举'!$C$2:$C$3,0))),"枚举错误",IF(OR(NOT(ISNUMBER(L7)),L7<0,NOT(ISNUMBER(M7)),M7<0,NOT(ISNUMBER(Q7)),Q7<0,AND(G7<>"",OR(NOT(ISNUMBER(G7)),G7<=0)),AND(H7<>"",OR(NOT(ISNUMBER(H7)),H7<=0)),AND(I7<>"",OR(NOT(ISNUMBER(I7)),I7<=0)),AND(J7<>"",OR(NOT(ISNUMBER(J7)),J7<=0))),"格式错误","可导入")))))
A8: =IF(COUNTA(B8:R8)=0,"待填写",IF(OR(B8="",C8="",D8="",E8="",F8="",K8="",NOT(ISNUMBER(L8)),NOT(ISNUMBER(M8)),P8="",NOT(ISNUMBER(Q8)),R8=""),"请补全必填",IF(OR(COUNTIF($B$5:$B$54,B8)>1,COUNTIF($C$5:$C$54,C8)>1),"ID重复",IF(OR(ISNA(MATCH(D8,'_枚举'!$Q$2:$Q$7,0)),ISNA(MATCH(E8,'_枚举'!$R$2:$R$7,0)),ISNA(MATCH(F8,'_枚举'!$S$2:$S$6,0)),ISNA(MATCH(K8,'_枚举'!$G$2:$G$3,0)),ISNA(MATCH(R8,'_枚举'!$C$2:$C$3,0))),"枚举错误",IF(OR(NOT(ISNUMBER(L8)),L8<0,NOT(ISNUMBER(M8)),M8<0,NOT(ISNUMBER(Q8)),Q8<0,AND(G8<>"",OR(NOT(ISNUMBER(G8)),G8<=0)),AND(H8<>"",OR(NOT(ISNUMBER(H8)),H8<=0)),AND(I8<>"",OR(NOT(ISNUMBER(I8)),I8<=0)),AND(J8<>"",OR(NOT(ISNUMBER(J8)),J8<=0))),"格式错误","可导入")))))
A9: =IF(COUNTA(B9:R9)=0,"待填写",IF(OR(B9="",C9="",D9="",E9="",F9="",K9="",NOT(ISNUMBER(L9)),NOT(ISNUMBER(M9)),P9="",NOT(ISNUMBER(Q9)),R9=""),"请补全必填",IF(OR(COUNTIF($B$5:$B$54,B9)>1,COUNTIF($C$5:$C$54,C9)>1),"ID重复",IF(OR(ISNA(MATCH(D9,'_枚举'!$Q$2:$Q$7,0)),ISNA(MATCH(E9,'_枚举'!$R$2:$R$7,0)),ISNA(MATCH(F9,'_枚举'!$S$2:$S$6,0)),ISNA(MATCH(K9,'_枚举'!$G$2:$G$3,0)),ISNA(MATCH(R9,'_枚举'!$C$2:$C$3,0))),"枚举错误",IF(OR(NOT(ISNUMBER(L9)),L9<0,NOT(ISNUMBER(M9)),M9<0,NOT(ISNUMBER(Q9)),Q9<0,AND(G9<>"",OR(NOT(ISNUMBER(G9)),G9<=0)),AND(H9<>"",OR(NOT(ISNUMBER(H9)),H9<=0)),AND(I9<>"",OR(NOT(ISNUMBER(I9)),I9<=0)),AND(J9<>"",OR(NOT(ISNUMBER(J9)),J9<=0))),"格式错误","可导入")))))
A10: =IF(COUNTA(B10:R10)=0,"待填写",IF(OR(B10="",C10="",D10="",E10="",F10="",K10="",NOT(ISNUMBER(L10)),NOT(ISNUMBER(M10)),P10="",NOT(ISNUMBER(Q10)),R10=""),"请补全必填",IF(OR(COUNTIF($B$5:$B$54,B10)>1,COUNTIF($C$5:$C$54,C10)>1),"ID重复",IF(OR(ISNA(MATCH(D10,'_枚举'!$Q$2:$Q$7,0)),ISNA(MATCH(E10,'_枚举'!$R$2:$R$7,0)),ISNA(MATCH(F10,'_枚举'!$S$2:$S$6,0)),ISNA(MATCH(K10,'_枚举'!$G$2:$G$3,0)),ISNA(MATCH(R10,'_枚举'!$C$2:$C$3,0))),"枚举错误",IF(OR(NOT(ISNUMBER(L10)),L10<0,NOT(ISNUMBER(M10)),M10<0,NOT(ISNUMBER(Q10)),Q10<0,AND(G10<>"",OR(NOT(ISNUMBER(G10)),G10<=0)),AND(H10<>"",OR(NOT(ISNUMBER(H10)),H10<=0)),AND(I10<>"",OR(NOT(ISNUMBER(I10)),I10<=0)),AND(J10<>"",OR(NOT(ISNUMBER(J10)),J10<=0))),"格式错误","可导入")))))
A11: =IF(COUNTA(B11:R11)=0,"待填写",IF(OR(B11="",C11="",D11="",E11="",F11="",K11="",NOT(ISNUMBER(L11)),NOT(ISNUMBER(M11)),P11="",NOT(ISNUMBER(Q11)),R11=""),"请补全必填",IF(OR(COUNTIF($B$5:$B$54,B11)>1,COUNTIF($C$5:$C$54,C11)>1),"ID重复",IF(OR(ISNA(MATCH(D11,'_枚举'!$Q$2:$Q$7,0)),ISNA(MATCH(E11,'_枚举'!$R$2:$R$7,0)),ISNA(MATCH(F11,'_枚举'!$S$2:$S$6,0)),ISNA(MATCH(K11,'_枚举'!$G$2:$G$3,0)),ISNA(MATCH(R11,'_枚举'!$C$2:$C$3,0))),"枚举错误",IF(OR(NOT(ISNUMBER(L11)),L11<0,NOT(ISNUMBER(M11)),M11<0,NOT(ISNUMBER(Q11)),Q11<0,AND(G11<>"",OR(NOT(ISNUMBER(G11)),G11<=0)),AND(H11<>"",OR(NOT(ISNUMBER(H11)),H11<=0)),AND(I11<>"",OR(NOT(ISNUMBER(I11)),I11<=0)),AND(J11<>"",OR(NOT(ISNUMBER(J11)),J11<=0))),"格式错误","可导入")))))
A12: =IF(COUNTA(B12:R12)=0,"待填写",IF(OR(B12="",C12="",D12="",E12="",F12="",K12="",NOT(ISNUMBER(L12)),NOT(ISNUMBER(M12)),P12="",NOT(ISNUMBER(Q12)),R12=""),"请补全必填",IF(OR(COUNTIF($B$5:$B$54,B12)>1,COUNTIF($C$5:$C$54,C12)>1),"ID重复",IF(OR(ISNA(MATCH(D12,'_枚举'!$Q$2:$Q$7,0)),ISNA(MATCH(E12,'_枚举'!$R$2:$R$7,0)),ISNA(MATCH(F12,'_枚举'!$S$2:$S$6,0)),ISNA(MATCH(K12,'_枚举'!$G$2:$G$3,0)),ISNA(MATCH(R12,'_枚举'!$C$2:$C$3,0))),"枚举错误",IF(OR(NOT(ISNUMBER(L12)),L12<0,NOT(ISNUMBER(M12)),M12<0,NOT(ISNUMBER(Q12)),Q12<0,AND(G12<>"",OR(NOT(ISNUMBER(G12)),G12<=0)),AND(H12<>"",OR(NOT(ISNUMBER(H12)),H12<=0)),AND(I12<>"",OR(NOT(ISNUMBER(I12)),I12<=0)),AND(J12<>"",OR(NOT(ISNUMBER(J12)),J12<=0))),"格式错误","可导入")))))
A13: =IF(COUNTA(B13:R13)=0,"待填写",IF(OR(B13="",C13="",D13="",E13="",F13="",K13="",NOT(ISNUMBER(L13)),NOT(ISNUMBER(M13)),P13="",NOT(ISNUMBER(Q13)),R13=""),"请补全必填",IF(OR(COUNTIF($B$5:$B$54,B13)>1,COUNTIF($C$5:$C$54,C13)>1),"ID重复",IF(OR(ISNA(MATCH(D13,'_枚举'!$Q$2:$Q$7,0)),ISNA(MATCH(E13,'_枚举'!$R$2:$R$7,0)),ISNA(MATCH(F13,'_枚举'!$S$2:$S$6,0)),ISNA(MATCH(K13,'_枚举'!$G$2:$G$3,0)),ISNA(MATCH(R13,'_枚举'!$C$2:$C$3,0))),"枚举错误",IF(OR(NOT(ISNUMBER(L13)),L13<0,NOT(ISNUMBER(M13)),M13<0,NOT(ISNUMBER(Q13)),Q13<0,AND(G13<>"",OR(NOT(ISNUMBER(G13)),G13<=0)),AND(H13<>"",OR(NOT(ISNUMBER(H13)),H13<=0)),AND(I13<>"",OR(NOT(ISNUMBER(I13)),I13<=0)),AND(J13<>"",OR(NOT(ISNUMBER(J13)),J13<=0))),"格式错误","可导入")))))
A14: =IF(COUNTA(B14:R14)=0,"待填写",IF(OR(B14="",C14="",D14="",E14="",F14="",K14="",NOT(ISNUMBER(L14)),NOT(ISNUMBER(M14)),P14="",NOT(ISNUMBER(Q14)),R14=""),"请补全必填",IF(OR(COUNTIF($B$5:$B$54,B14)>1,COUNTIF($C$5:$C$54,C14)>1),"ID重复",IF(OR(ISNA(MATCH(D14,'_枚举'!$Q$2:$Q$7,0)),ISNA(MATCH(E14,'_枚举'!$R$2:$R$7,0)),ISNA(MATCH(F14,'_枚举'!$S$2:$S$6,0)),ISNA(MATCH(K14,'_枚举'!$G$2:$G$3,0)),ISNA(MATCH(R14,'_枚举'!$C$2:$C$3,0))),"枚举错误",IF(OR(NOT(ISNUMBER(L14)),L14<0,NOT(ISNUMBER(M14)),M14<0,NOT(ISNUMBER(Q14)),Q14<0,AND(G14<>"",OR(NOT(ISNUMBER(G14)),G14<=0)),AND(H14<>"",OR(NOT(ISNUMBER(H14)),H14<=0)),AND(I14<>"",OR(NOT(ISNUMBER(I14)),I14<=0)),AND(J14<>"",OR(NOT(ISNUMBER(J14)),J14<=0))),"格式错误","可导入")))))
A15: =IF(COUNTA(B15:R15)=0,"待填写",IF(OR(B15="",C15="",D15="",E15="",F15="",K15="",NOT(ISNUMBER(L15)),NOT(ISNUMBER(M15)),P15="",NOT(ISNUMBER(Q15)),R15=""),"请补全必填",IF(OR(COUNTIF($B$5:$B$54,B15)>1,COUNTIF($C$5:$C$54,C15)>1),"ID重复",IF(OR(ISNA(MATCH(D15,'_枚举'!$Q$2:$Q$7,0)),ISNA(MATCH(E15,'_枚举'!$R$2:$R$7,0)),ISNA(MATCH(F15,'_枚举'!$S$2:$S$6,0)),ISNA(MATCH(K15,'_枚举'!$G$2:$G$3,0)),ISNA(MATCH(R15,'_枚举'!$C$2:$C$3,0))),"枚举错误",IF(OR(NOT(ISNUMBER(L15)),L15<0,NOT(ISNUMBER(M15)),M15<0,NOT(ISNUMBER(Q15)),Q15<0,AND(G15<>"",OR(NOT(ISNUMBER(G15)),G15<=0)),AND(H15<>"",OR(NOT(ISNUMBER(H15)),H15<=0)),AND(I15<>"",OR(NOT(ISNUMBER(I15)),I15<=0)),AND(J15<>"",OR(NOT(ISNUMBER(J15)),J15<=0))),"格式错误","可导入")))))
A16: =IF(COUNTA(B16:R16)=0,"待填写",IF(OR(B16="",C16="",D16="",E16="",F16="",K16="",NOT(ISNUMBER(L16)),NOT(ISNUMBER(M16)),P16="",NOT(ISNUMBER(Q16)),R16=""),"请补全必填",IF(OR(COUNTIF($B$5:$B$54,B16)>1,COUNTIF($C$5:$C$54,C16)>1),"ID重复",IF(OR(ISNA(MATCH(D16,'_枚举'!$Q$2:$Q$7,0)),ISNA(MATCH(E16,'_枚举'!$R$2:$R$7,0)),ISNA(MATCH(F16,'_枚举'!$S$2:$S$6,0)),ISNA(MATCH(K16,'_枚举'!$G$2:$G$3,0)),ISNA(MATCH(R16,'_枚举'!$C$2:$C$3,0))),"枚举错误",IF(OR(NOT(ISNUMBER(L16)),L16<0,NOT(ISNUMBER(M16)),M16<0,NOT(ISNUMBER(Q16)),Q16<0,AND(G16<>"",OR(NOT(ISNUMBER(G16)),G16<=0)),AND(H16<>"",OR(NOT(ISNUMBER(H16)),H16<=0)),AND(I16<>"",OR(NOT(ISNUMBER(I16)),I16<=0)),AND(J16<>"",OR(NOT(ISNUMBER(J16)),J16<=0))),"格式错误","可导入")))))
A17: =IF(COUNTA(B17:R17)=0,"待填写",IF(OR(B17="",C17="",D17="",E17="",F17="",K17="",NOT(ISNUMBER(L17)),NOT(ISNUMBER(M17)),P17="",NOT(ISNUMBER(Q17)),R17=""),"请补全必填",IF(OR(COUNTIF($B$5:$B$54,B17)>1,COUNTIF($C$5:$C$54,C17)>1),"ID重复",IF(OR(ISNA(MATCH(D17,'_枚举'!$Q$2:$Q$7,0)),ISNA(MATCH(E17,'_枚举'!$R$2:$R$7,0)),ISNA(MATCH(F17,'_枚举'!$S$2:$S$6,0)),ISNA(MATCH(K17,'_枚举'!$G$2:$G$3,0)),ISNA(MATCH(R17,'_枚举'!$C$2:$C$3,0))),"枚举错误",IF(OR(NOT(ISNUMBER(L17)),L17<0,NOT(ISNUMBER(M17)),M17<0,NOT(ISNUMBER(Q17)),Q17<0,AND(G17<>"",OR(NOT(ISNUMBER(G17)),G17<=0)),AND(H17<>"",OR(NOT(ISNUMBER(H17)),H17<=0)),AND(I17<>"",OR(NOT(ISNUMBER(I17)),I17<=0)),AND(J17<>"",OR(NOT(ISNUMBER(J17)),J17<=0))),"格式错误","可导入")))))
A18: =IF(COUNTA(B18:R18)=0,"待填写",IF(OR(B18="",C18="",D18="",E18="",F18="",K18="",NOT(ISNUMBER(L18)),NOT(ISNUMBER(M18)),P18="",NOT(ISNUMBER(Q18)),R18=""),"请补全必填",IF(OR(COUNTIF($B$5:$B$54,B18)>1,COUNTIF($C$5:$C$54,C18)>1),"ID重复",IF(OR(ISNA(MATCH(D18,'_枚举'!$Q$2:$Q$7,0)),ISNA(MATCH(E18,'_枚举'!$R$2:$R$7,0)),ISNA(MATCH(F18,'_枚举'!$S$2:$S$6,0)),ISNA(MATCH(K18,'_枚举'!$G$2:$G$3,0)),ISNA(MATCH(R18,'_枚举'!$C$2:$C$3,0))),"枚举错误",IF(OR(NOT(ISNUMBER(L18)),L18<0,NOT(ISNUMBER(M18)),M18<0,NOT(ISNUMBER(Q18)),Q18<0,AND(G18<>"",OR(NOT(ISNUMBER(G18)),G18<=0)),AND(H18<>"",OR(NOT(ISNUMBER(H18)),H18<=0)),AND(I18<>"",OR(NOT(ISNUMBER(I18)),I18<=0)),AND(J18<>"",OR(NOT(ISNUMBER(J18)),J18<=0))),"格式错误","可导入")))))
... A54: =IF(COUNTA(B54:R54)=0,"待填写",IF(OR(B54="",C54="",D54="",E54="",F54="",K54="",NOT(ISNUMBER(L54)),NOT(ISNUMBER(M54)),P54="",NOT(ISNUMBER(Q54)),R54=""),"请补全必填",IF(OR(COUNTIF($B$5:$B$54,B54)>1,COUNTIF($C$5:$C$54,C54)>1),"ID重复",IF(OR(ISNA(MATCH(D54,'_枚举'!$Q$2:$Q$7,0)),ISNA(MATCH(E54,'_枚举'!$R$2:$R$7,0)),ISNA(MATCH(F54,'_枚举'!$S$2:$S$6,0)),ISNA(MATCH(K54,'_枚举'!$G$2:$G$3,0)),ISNA(MATCH(R54,'_枚举'!$C$2:$C$3,0))),"枚举错误",IF(OR(NOT(ISNUMBER(L54)),L54<0,NOT(ISNUMBER(M54)),M54<0,NOT(ISNUMBER(Q54)),Q54<0,AND(G54<>"",OR(NOT(ISNUMBER(G54)),G54<=0)),AND(H54<>"",OR(NOT(ISNUMBER(H54)),H54<=0)),AND(I54<>"",OR(NOT(ISNUMBER(I54)),I54<=0)),AND(J54<>"",OR(NOT(ISNUMBER(J54)),J54<=0))),"格式错误","可导入")))))

Sheet 库存批次
A1: 库存批次｜同一 SKU 的每次进货分别记录
A3: 批次外观备注只写肉眼可见的简单描述；不要求透明度、棉絮、冰裂、黑点、矿缺或处理方式判断。
A4: 导入状态 | B4: lot_id* | C4: sku* | D4: 供应商编号 | E4: 供应商名称 | F4: 采购日期 | G4: 到货日期 | H4: 批次数量* | I4: 当前可用数量* | J4: 锁定数量* | K4: 单位* | L4: 批次成本* | M4: 币种* | N4: 市场品质等级* | O4: 品质信息来源* | P4: 批次外观备注 | Q4: 是否有实拍图片* | R4: 是否经过人工确认* | S4: 是否可用于 AI 推荐* | T4: 质检状态* | U4: 备注
A5: =IF(COUNTA(B5:U5)=0,"待填写",IF(OR(B5="",C5="",NOT(ISNUMBER(H5)),NOT(ISNUMBER(I5)),NOT(ISNUMBER(J5)),K5="",NOT(ISNUMBER(L5)),M5="",N5="",O5="",Q5="",R5="",S5="",T5=""),"请补全必填",IF(COUNTIF($B$5:$B$104,B5)>1,"ID重复",IF(COUNTIF('珠子SKU'!$C$5:$C$104,C5)=0,"关联不存在",IF(OR(ISNA(MATCH(K5,'_枚举'!$H$2:$H$5,0)),ISNA(MATCH(M5,'_枚举'!$G$2:$G$3,0)),ISNA(MATCH(N5,'_枚举'!$A$2:$A$4,0)),ISNA(MATCH(O5,'_枚举'!$B$2:$B$5,0)),ISNA(MATCH(Q5,'_枚举'!$C$2:$C$3,0)),ISNA(MATCH(R5,'_枚举'!$C$2:$C$3,0)),ISNA(MATCH(S5,'_枚举'!$C$2:$C$3,0)),ISNA(MATCH(T5,'_枚举'!$I$2:$I$5,0))),"枚举错误",IF(OR(AND(F5<>"",NOT(ISNUMBER(F5))),AND(G5<>"",NOT(ISNUMBER(G5))),NOT(ISNUMBER(H5)),H5<0,NOT(ISNUMBER(I5)),I5<0,NOT(ISNUMBER(J5)),J5<0,I5+J5>H5,NOT(ISNUMBER(L5)),L5<0),"格式错误",IF(AND(S5="TRUE",OR(Q5<>"TRUE",R5<>"TRUE",N5="UNKNOWN",T5<>"PASSED")),"待人工复核","可导入"))))))) | B5: lot-aq-202607-01 | C5: AQ-CNY-8 | D5: SUP-001 | E5: 示例供应商 | H5: 100 | I5: 100 | J5: 0 | K5: BEAD | L5: 50400 | M5: CNY | N5: COMMERCIAL_A | O5: SUPPLIER_CLAIM | P5: 普通市场货，以实拍图片为准。 | Q5: TRUE | R5: TRUE | S5: TRUE | T5: PASSED | U5: 示例，可修改
A6: =IF(COUNTA(B6:U6)=0,"待填写",IF(OR(B6="",C6="",NOT(ISNUMBER(H6)),NOT(ISNUMBER(I6)),NOT(ISNUMBER(J6)),K6="",NOT(ISNUMBER(L6)),M6="",N6="",O6="",Q6="",R6="",S6="",T6=""),"请补全必填",IF(COUNTIF($B$5:$B$104,B6)>1,"ID重复",IF(COUNTIF('珠子SKU'!$C$5:$C$104,C6)=0,"关联不存在",IF(OR(ISNA(MATCH(K6,'_枚举'!$H$2:$H$5,0)),ISNA(MATCH(M6,'_枚举'!$G$2:$G$3,0)),ISNA(MATCH(N6,'_枚举'!$A$2:$A$4,0)),ISNA(MATCH(O6,'_枚举'!$B$2:$B$5,0)),ISNA(MATCH(Q6,'_枚举'!$C$2:$C$3,0)),ISNA(MATCH(R6,'_枚举'!$C$2:$C$3,0)),ISNA(MATCH(S6,'_枚举'!$C$2:$C$3,0)),ISNA(MATCH(T6,'_枚举'!$I$2:$I$5,0))),"枚举错误",IF(OR(AND(F6<>"",NOT(ISNUMBER(F6))),AND(G6<>"",NOT(ISNUMBER(G6))),NOT(ISNUMBER(H6)),H6<0,NOT(ISNUMBER(I6)),I6<0,NOT(ISNUMBER(J6)),J6<0,I6+J6>H6,NOT(ISNUMBER(L6)),L6<0),"格式错误",IF(AND(S6="TRUE",OR(Q6<>"TRUE",R6<>"TRUE",N6="UNKNOWN",T6<>"PASSED")),"待人工复核","可导入"))))))) | B6: lot-am-202607-01 | C6: AM-CNY-8 | D6: SUP-001 | E6: 示例供应商 | H6: 100 | I6: 96 | J6: 4 | K6: BEAD | L6: 28500 | M6: CNY | N6: NEAR_COMMERCIAL_A | O6: MARKET_DESCRIPTION | P6: 本批次整体偏浅紫，珠子颜色存在差异。 | Q6: TRUE | R6: TRUE | S6: TRUE | T6: PASSED | U6: 示例，可修改
A7: =IF(COUNTA(B7:U7)=0,"待填写",IF(OR(B7="",C7="",NOT(ISNUMBER(H7)),NOT(ISNUMBER(I7)),NOT(ISNUMBER(J7)),K7="",NOT(ISNUMBER(L7)),M7="",N7="",O7="",Q7="",R7="",S7="",T7=""),"请补全必填",IF(COUNTIF($B$5:$B$104,B7)>1,"ID重复",IF(COUNTIF('珠子SKU'!$C$5:$C$104,C7)=0,"关联不存在",IF(OR(ISNA(MATCH(K7,'_枚举'!$H$2:$H$5,0)),ISNA(MATCH(M7,'_枚举'!$G$2:$G$3,0)),ISNA(MATCH(N7,'_枚举'!$A$2:$A$4,0)),ISNA(MATCH(O7,'_枚举'!$B$2:$B$5,0)),ISNA(MATCH(Q7,'_枚举'!$C$2:$C$3,0)),ISNA(MATCH(R7,'_枚举'!$C$2:$C$3,0)),ISNA(MATCH(S7,'_枚举'!$C$2:$C$3,0)),ISNA(MATCH(T7,'_枚举'!$I$2:$I$5,0))),"枚举错误",IF(OR(AND(F7<>"",NOT(ISNUMBER(F7))),AND(G7<>"",NOT(ISNUMBER(G7))),NOT(ISNUMBER(H7)),H7<0,NOT(ISNUMBER(I7)),I7<0,NOT(ISNUMBER(J7)),J7<0,I7+J7>H7,NOT(ISNUMBER(L7)),L7<0),"格式错误",IF(AND(S7="TRUE",OR(Q7<>"TRUE",R7<>"TRUE",N7="UNKNOWN",T7<>"PASSED")),"待人工复核","可导入")))))))
A8: =IF(COUNTA(B8:U8)=0,"待填写",IF(OR(B8="",C8="",NOT(ISNUMBER(H8)),NOT(ISNUMBER(I8)),NOT(ISNUMBER(J8)),K8="",NOT(ISNUMBER(L8)),M8="",N8="",O8="",Q8="",R8="",S8="",T8=""),"请补全必填",IF(COUNTIF($B$5:$B$104,B8)>1,"ID重复",IF(COUNTIF('珠子SKU'!$C$5:$C$104,C8)=0,"关联不存在",IF(OR(ISNA(MATCH(K8,'_枚举'!$H$2:$H$5,0)),ISNA(MATCH(M8,'_枚举'!$G$2:$G$3,0)),ISNA(MATCH(N8,'_枚举'!$A$2:$A$4,0)),ISNA(MATCH(O8,'_枚举'!$B$2:$B$5,0)),ISNA(MATCH(Q8,'_枚举'!$C$2:$C$3,0)),ISNA(MATCH(R8,'_枚举'!$C$2:$C$3,0)),ISNA(MATCH(S8,'_枚举'!$C$2:$C$3,0)),ISNA(MATCH(T8,'_枚举'!$I$2:$I$5,0))),"枚举错误",IF(OR(AND(F8<>"",NOT(ISNUMBER(F8))),AND(G8<>"",NOT(ISNUMBER(G8))),NOT(ISNUMBER(H8)),H8<0,NOT(ISNUMBER(I8)),I8<0,NOT(ISNUMBER(J8)),J8<0,I8+J8>H8,NOT(ISNUMBER(L8)),L8<0),"格式错误",IF(AND(S8="TRUE",OR(Q8<>"TRUE",R8<>"TRUE",N8="UNKNOWN",T8<>"PASSED")),"待人工复核","可导入")))))))
A9: =IF(COUNTA(B9:U9)=0,"待填写",IF(OR(B9="",C9="",NOT(ISNUMBER(H9)),NOT(ISNUMBER(I9)),NOT(ISNUMBER(J9)),K9="",NOT(ISNUMBER(L9)),M9="",N9="",O9="",Q9="",R9="",S9="",T9=""),"请补全必填",IF(COUNTIF($B$5:$B$104,B9)>1,"ID重复",IF(COUNTIF('珠子SKU'!$C$5:$C$104,C9)=0,"关联不存在",IF(OR(ISNA(MATCH(K9,'_枚举'!$H$2:$H$5,0)),ISNA(MATCH(M9,'_枚举'!$G$2:$G$3,0)),ISNA(MATCH(N9,'_枚举'!$A$2:$A$4,0)),ISNA(MATCH(O9,'_枚举'!$B$2:$B$5,0)),ISNA(MATCH(Q9,'_枚举'!$C$2:$C$3,0)),ISNA(MATCH(R9,'_枚举'!$C$2:$C$3,0)),ISNA(MATCH(S9,'_枚举'!$C$2:$C$3,0)),ISNA(MATCH(T9,'_枚举'!$I$2:$I$5,0))),"枚举错误",IF(OR(AND(F9<>"",NOT(ISNUMBER(F9))),AND(G9<>"",NOT(ISNUMBER(G9))),NOT(ISNUMBER(H9)),H9<0,NOT(ISNUMBER(I9)),I9<0,NOT(ISNUMBER(J9)),J9<0,I9+J9>H9,NOT(ISNUMBER(L9)),L9<0),"格式错误",IF(AND(S9="TRUE",OR(Q9<>"TRUE",R9<>"TRUE",N9="UNKNOWN",T9<>"PASSED")),"待人工复核","可导入")))))))
A10: =IF(COUNTA(B10:U10)=0,"待填写",IF(OR(B10="",C10="",NOT(ISNUMBER(H10)),NOT(ISNUMBER(I10)),NOT(ISNUMBER(J10)),K10="",NOT(ISNUMBER(L10)),M10="",N10="",O10="",Q10="",R10="",S10="",T10=""),"请补全必填",IF(COUNTIF($B$5:$B$104,B10)>1,"ID重复",IF(COUNTIF('珠子SKU'!$C$5:$C$104,C10)=0,"关联不存在",IF(OR(ISNA(MATCH(K10,'_枚举'!$H$2:$H$5,0)),ISNA(MATCH(M10,'_枚举'!$G$2:$G$3,0)),ISNA(MATCH(N10,'_枚举'!$A$2:$A$4,0)),ISNA(MATCH(O10,'_枚举'!$B$2:$B$5,0)),ISNA(MATCH(Q10,'_枚举'!$C$2:$C$3,0)),ISNA(MATCH(R10,'_枚举'!$C$2:$C$3,0)),ISNA(MATCH(S10,'_枚举'!$C$2:$C$3,0)),ISNA(MATCH(T10,'_枚举'!$I$2:$I$5,0))),"枚举错误",IF(OR(AND(F10<>"",NOT(ISNUMBER(F10))),AND(G10<>"",NOT(ISNUMBER(G10))),NOT(ISNUMBER(H10)),H10<0,NOT(ISNUMBER(I10)),I10<0,NOT(ISNUMBER(J10)),J10<0,I10+J10>H10,NOT(ISNUMBER(L10)),L10<0),"格式错误",IF(AND(S10="TRUE",OR(Q10<>"TRUE",R10<>"TRUE",N10="UNKNOWN",T10<>"PASSED")),"待人工复核","可导入")))))))
A11: =IF(COUNTA(B11:U11)=0,"待填写",IF(OR(B11="",C11="",NOT(ISNUMBER(H11)),NOT(ISNUMBER(I11)),NOT(ISNUMBER(J11)),K11="",NOT(ISNUMBER(L11)),M11="",N11="",O11="",Q11="",R11="",S11="",T11=""),"请补全必填",IF(COUNTIF($B$5:$B$104,B11)>1,"ID重复",IF(COUNTIF('珠子SKU'!$C$5:$C$104,C11)=0,"关联不存在",IF(OR(ISNA(MATCH(K11,'_枚举'!$H$2:$H$5,0)),ISNA(MATCH(M11,'_枚举'!$G$2:$G$3,0)),ISNA(MATCH(N11,'_枚举'!$A$2:$A$4,0)),ISNA(MATCH(O11,'_枚举'!$B$2:$B$5,0)),ISNA(MATCH(Q11,'_枚举'!$C$2:$C$3,0)),ISNA(MATCH(R11,'_枚举'!$C$2:$C$3,0)),ISNA(MATCH(S11,'_枚举'!$C$2:$C$3,0)),ISNA(MATCH(T11,'_枚举'!$I$2:$I$5,0))),"枚举错误",IF(OR(AND(F11<>"",NOT(ISNUMBER(F11))),AND(G11<>"",NOT(ISNUMBER(G11))),NOT(ISNUMBER(H11)),H11<0,NOT(ISNUMBER(I11)),I11<0,NOT(ISNUMBER(J11)),J11<0,I11+J11>H11,NOT(ISNUMBER(L11)),L11<0),"格式错误",IF(AND(S11="TRUE",OR(Q11<>"TRUE",R11<>"TRUE",N11="UNKNOWN",T11<>"PASSED")),"待人工复核","可导入")))))))
A12: =IF(COUNTA(B12:U12)=0,"待填写",IF(OR(B12="",C12="",NOT(ISNUMBER(H12)),NOT(ISNUMBER(I12)),NOT(ISNUMBER(J12)),K12="",NOT(ISNUMBER(L12)),M12="",N12="",O12="",Q12="",R12="",S12="",T12=""),"请补全必填",IF(COUNTIF($B$5:$B$104,B12)>1,"ID重复",IF(COUNTIF('珠子SKU'!$C$5:$C$104,C12)=0,"关联不存在",IF(OR(ISNA(MATCH(K12,'_枚举'!$H$2:$H$5,0)),ISNA(MATCH(M12,'_枚举'!$G$2:$G$3,0)),ISNA(MATCH(N12,'_枚举'!$A$2:$A$4,0)),ISNA(MATCH(O12,'_枚举'!$B$2:$B$5,0)),ISNA(MATCH(Q12,'_枚举'!$C$2:$C$3,0)),ISNA(MATCH(R12,'_枚举'!$C$2:$C$3,0)),ISNA(MATCH(S12,'_枚举'!$C$2:$C$3,0)),ISNA(MATCH(T12,'_枚举'!$I$2:$I$5,0))),"枚举错误",IF(OR(AND(F12<>"",NOT(ISNUMBER(F12))),AND(G12<>"",NOT(ISNUMBER(G12))),NOT(ISNUMBER(H12)),H12<0,NOT(ISNUMBER(I12)),I12<0,NOT(ISNUMBER(J12)),J12<0,I12+J12>H12,NOT(ISNUMBER(L12)),L12<0),"格式错误",IF(AND(S12="TRUE",OR(Q12<>"TRUE",R12<>"TRUE",N12="UNKNOWN",T12<>"PASSED")),"待人工复核","可导入")))))))
A13: =IF(COUNTA(B13:U13)=0,"待填写",IF(OR(B13="",C13="",NOT(ISNUMBER(H13)),NOT(ISNUMBER(I13)),NOT(ISNUMBER(J13)),K13="",NOT(ISNUMBER(L13)),M13="",N13="",O13="",Q13="",R13="",S13="",T13=""),"请补全必填",IF(COUNTIF($B$5:$B$104,B13)>1,"ID重复",IF(COUNTIF('珠子SKU'!$C$5:$C$104,C13)=0,"关联不存在",IF(OR(ISNA(MATCH(K13,'_枚举'!$H$2:$H$5,0)),ISNA(MATCH(M13,'_枚举'!$G$2:$G$3,0)),ISNA(MATCH(N13,'_枚举'!$A$2:$A$4,0)),ISNA(MATCH(O13,'_枚举'!$B$2:$B$5,0)),ISNA(MATCH(Q13,'_枚举'!$C$2:$C$3,0)),ISNA(MATCH(R13,'_枚举'!$C$2:$C$3,0)),ISNA(MATCH(S13,'_枚举'!$C$2:$C$3,0)),ISNA(MATCH(T13,'_枚举'!$I$2:$I$5,0))),"枚举错误",IF(OR(AND(F13<>"",NOT(ISNUMBER(F13))),AND(G13<>"",NOT(ISNUMBER(G13))),NOT(ISNUMBER(H13)),H13<0,NOT(ISNUMBER(I13)),I13<0,NOT(ISNUMBER(J13)),J13<0,I13+J13>H13,NOT(ISNUMBER(L13)),L13<0),"格式错误",IF(AND(S13="TRUE",OR(Q13<>"TRUE",R13<>"TRUE",N13="UNKNOWN",T13<>"PASSED")),"待人工复核","可导入")))))))
A14: =IF(COUNTA(B14:U14)=0,"待填写",IF(OR(B14="",C14="",NOT(ISNUMBER(H14)),NOT(ISNUMBER(I14)),NOT(ISNUMBER(J14)),K14="",NOT(ISNUMBER(L14)),M14="",N14="",O14="",Q14="",R14="",S14="",T14=""),"请补全必填",IF(COUNTIF($B$5:$B$104,B14)>1,"ID重复",IF(COUNTIF('珠子SKU'!$C$5:$C$104,C14)=0,"关联不存在",IF(OR(ISNA(MATCH(K14,'_枚举'!$H$2:$H$5,0)),ISNA(MATCH(M14,'_枚举'!$G$2:$G$3,0)),ISNA(MATCH(N14,'_枚举'!$A$2:$A$4,0)),ISNA(MATCH(O14,'_枚举'!$B$2:$B$5,0)),ISNA(MATCH(Q14,'_枚举'!$C$2:$C$3,0)),ISNA(MATCH(R14,'_枚举'!$C$2:$C$3,0)),ISNA(MATCH(S14,'_枚举'!$C$2:$C$3,0)),ISNA(MATCH(T14,'_枚举'!$I$2:$I$5,0))),"枚举错误",IF(OR(AND(F14<>"",NOT(ISNUMBER(F14))),AND(G14<>"",NOT(ISNUMBER(G14))),NOT(ISNUMBER(H14)),H14<0,NOT(ISNUMBER(I14)),I14<0,NOT(ISNUMBER(J14)),J14<0,I14+J14>H14,NOT(ISNUMBER(L14)),L14<0),"格式错误",IF(AND(S14="TRUE",OR(Q14<>"TRUE",R14<>"TRUE",N14="UNKNOWN",T14<>"PASSED")),"待人工复核","可导入")))))))
A15: =IF(COUNTA(B15:U15)=0,"待填写",IF(OR(B15="",C15="",NOT(ISNUMBER(H15)),NOT(ISNUMBER(I15)),NOT(ISNUMBER(J15)),K15="",NOT(ISNUMBER(L15)),M15="",N15="",O15="",Q15="",R15="",S15="",T15=""),"请补全必填",IF(COUNTIF($B$5:$B$104,B15)>1,"ID重复",IF(COUNTIF('珠子SKU'!$C$5:$C$104,C15)=0,"关联不存在",IF(OR(ISNA(MATCH(K15,'_枚举'!$H$2:$H$5,0)),ISNA(MATCH(M15,'_枚举'!$G$2:$G$3,0)),ISNA(MATCH(N15,'_枚举'!$A$2:$A$4,0)),ISNA(MATCH(O15,'_枚举'!$B$2:$B$5,0)),ISNA(MATCH(Q15,'_枚举'!$C$2:$C$3,0)),ISNA(MATCH(R15,'_枚举'!$C$2:$C$3,0)),ISNA(MATCH(S15,'_枚举'!$C$2:$C$3,0)),ISNA(MATCH(T15,'_枚举'!$I$2:$I$5,0))),"枚举错误",IF(OR(AND(F15<>"",NOT(ISNUMBER(F15))),AND(G15<>"",NOT(ISNUMBER(G15))),NOT(ISNUMBER(H15)),H15<0,NOT(ISNUMBER(I15)),I15<0,NOT(ISNUMBER(J15)),J15<0,I15+J15>H15,NOT(ISNUMBER(L15)),L15<0),"格式错误",IF(AND(S15="TRUE",OR(Q15<>"TRUE",R15<>"TRUE",N15="UNKNOWN",T15<>"PASSED")),"待人工复核","可导入")))))))
A16: =IF(COUNTA(B16:U16)=0,"待填写",IF(OR(B16="",C16="",NOT(ISNUMBER(H16)),NOT(ISNUMBER(I16)),NOT(ISNUMBER(J16)),K16="",NOT(ISNUMBER(L16)),M16="",N16="",O16="",Q16="",R16="",S16="",T16=""),"请补全必填",IF(COUNTIF($B$5:$B$104,B16)>1,"ID重复",IF(COUNTIF('珠子SKU'!$C$5:$C$104,C16)=0,"关联不存在",IF(OR(ISNA(MATCH(K16,'_枚举'!$H$2:$H$5,0)),ISNA(MATCH(M16,'_枚举'!$G$2:$G$3,0)),ISNA(MATCH(N16,'_枚举'!$A$2:$A$4,0)),ISNA(MATCH(O16,'_枚举'!$B$2:$B$5,0)),ISNA(MATCH(Q16,'_枚举'!$C$2:$C$3,0)),ISNA(MATCH(R16,'_枚举'!$C$2:$C$3,0)),ISNA(MATCH(S16,'_枚举'!$C$2:$C$3,0)),ISNA(MATCH(T16,'_枚举'!$I$2:$I$5,0))),"枚举错误",IF(OR(AND(F16<>"",NOT(ISNUMBER(F16))),AND(G16<>"",NOT(ISNUMBER(G16))),NOT(ISNUMBER(H16)),H16<0,NOT(ISNUMBER(I16)),I16<0,NOT(ISNUMBER(J16)),J16<0,I16+J16>H16,NOT(ISNUMBER(L16)),L16<0),"格式错误",IF(AND(S16="TRUE",OR(Q16<>"TRUE",R16<>"TRUE",N16="UNKNOWN",T16<>"PASSED")),"待人工复核","可导入")))))))
A17: =IF(COUNTA(B17:U17)=0,"待填写",IF(OR(B17="",C17="",NOT(ISNUMBER(H17)),NOT(ISNUMBER(I17)),NOT(ISNUMBER(J17)),K17="",NOT(ISNUMBER(L17)),M17="",N17="",O17="",Q17="",R17="",S17="",T17=""),"请补全必填",IF(COUNTIF($B$5:$B$104,B17)>1,"ID重复",IF(COUNTIF('珠子SKU'!$C$5:$C$104,C17)=0,"关联不存在",IF(OR(ISNA(MATCH(K17,'_枚举'!$H$2:$H$5,0)),ISNA(MATCH(M17,'_枚举'!$G$2:$G$3,0)),ISNA(MATCH(N17,'_枚举'!$A$2:$A$4,0)),ISNA(MATCH(O17,'_枚举'!$B$2:$B$5,0)),ISNA(MATCH(Q17,'_枚举'!$C$2:$C$3,0)),ISNA(MATCH(R17,'_枚举'!$C$2:$C$3,0)),ISNA(MATCH(S17,'_枚举'!$C$2:$C$3,0)),ISNA(MATCH(T17,'_枚举'!$I$2:$I$5,0))),"枚举错误",IF(OR(AND(F17<>"",NOT(ISNUMBER(F17))),AND(G17<>"",NOT(ISNUMBER(G17))),NOT(ISNUMBER(H17)),H17<0,NOT(ISNUMBER(I17)),I17<0,NOT(ISNUMBER(J17)),J17<0,I17+J17>H17,NOT(ISNUMBER(L17)),L17<0),"格式错误",IF(AND(S17="TRUE",OR(Q17<>"TRUE",R17<>"TRUE",N17="UNKNOWN",T17<>"PASSED")),"待人工复核","可导入")))))))
A18: =IF(COUNTA(B18:U18)=0,"待填写",IF(OR(B18="",C18="",NOT(ISNUMBER(H18)),NOT(ISNUMBER(I18)),NOT(ISNUMBER(J18)),K18="",NOT(ISNUMBER(L18)),M18="",N18="",O18="",Q18="",R18="",S18="",T18=""),"请补全必填",IF(COUNTIF($B$5:$B$104,B18)>1,"ID重复",IF(COUNTIF('珠子SKU'!$C$5:$C$104,C18)=0,"关联不存在",IF(OR(ISNA(MATCH(K18,'_枚举'!$H$2:$H$5,0)),ISNA(MATCH(M18,'_枚举'!$G$2:$G$3,0)),ISNA(MATCH(N18,'_枚举'!$A$2:$A$4,0)),ISNA(MATCH(O18,'_枚举'!$B$2:$B$5,0)),ISNA(MATCH(Q18,'_枚举'!$C$2:$C$3,0)),ISNA(MATCH(R18,'_枚举'!$C$2:$C$3,0)),ISNA(MATCH(S18,'_枚举'!$C$2:$C$3,0)),ISNA(MATCH(T18,'_枚举'!$I$2:$I$5,0))),"枚举错误",IF(OR(AND(F18<>"",NOT(ISNUMBER(F18))),AND(G18<>"",NOT(ISNUMBER(G18))),NOT(ISNUMBER(H18)),H18<0,NOT(ISNUMBER(I18)),I18<0,NOT(ISNUMBER(J18)),J18<0,I18+J18>H18,NOT(ISNUMBER(L18)),L18<0),"格式错误",IF(AND(S18="TRUE",OR(Q18<>"TRUE",R18<>"TRUE",N18="UNKNOWN",T18<>"PASSED")),"待人工复核","可导入")))))))
... A104: =IF(COUNTA(B104:U104)=0,"待填写",IF(OR(B104="",C104="",NOT(ISNUMBER(H104)),NOT(ISNUMBER(I104)),NOT(ISNUMBER(J104)),K104="",NOT(ISNUMBER(L104)),M104="",N104="",O104="",Q104="",R104="",S104="",T104=""),"请补全必填",IF(COUNTIF($B$5:$B$104,B104)>1,"ID重复",IF(COUNTIF('珠子SKU'!$C$5:$C$104,C104)=0,"关联不存在",IF(OR(ISNA(MATCH(K104,'_枚举'!$H$2:$H$5,0)),ISNA(MATCH(M104,'_枚举'!$G$2:$G$3,0)),ISNA(MATCH(N104,'_枚举'!$A$2:$A$4,0)),ISNA(MATCH(O104,'_枚举'!$B$2:$B$5,0)),ISNA(MATCH(Q104,'_枚举'!$C$2:$C$3,0)),ISNA(MATCH(R104,'_枚举'!$C$2:$C$3,0)),ISNA(MATCH(S104,'_枚举'!$C$2:$C$3,0)),ISNA(MATCH(T104,'_枚举'!$I$2:$I$5,0))),"枚举错误",IF(OR(AND(F104<>"",NOT(ISNUMBER(F104))),AND(G104<>"",NOT(ISNUMBER(G104))),NOT(ISNUMBER(H104)),H104<0,NOT(ISNUMBER(I104)),I104<0,NOT(ISNUMBER(J104)),J104<0,I104+J104>H104,NOT(ISNUMBER(L104)),L104<0),"格式错误",IF(AND(S104="TRUE",OR(Q104<>"TRUE",R104<>"TRUE",N104="UNKNOWN",T104<>"PASSED")),"待人工复核","可导入")))))))

Sheet 图片资产
A1: 图片资产｜一张图片一行
A3: 图片品质等级只能来自用户、供应商或已有记录；程序不得根据图片漂亮程度猜测。来源、授权、实拍/AI 属性必须可追溯。
A4: 导入状态 | B4: image_id* | C4: crystal_id | D4: sku | E4: lot_id | F4: 文件名* | G4: 相对路径* | H4: image_type* | I4: 是否真实实拍* | J4: 来源类型* | K4: 来源平台 | L4: 来源链接 | M4: 来源作者或供应商 | N4: 使用权限* | O4: 是否允许 AI 训练* | P4: 是否允许商业使用* | Q4: 是否允许公开展示* | R4: 市场品质等级* | S4: 品质信息来源* | T4: 是否代表当前实际货品* | U4: 是否过度修图* | V4: 是否疑似 AI 图片* | W4: 文件哈希 | X4: 人工复核状态* | Y4: 复核人 | Z4: 备注
